Workbook
Name Print_Titles: SUM!$1:$7
Name Print_Titles: '2026'!$1:$7
Name Print_Titles: '2025'!$1:$7
Name Print_Titles: '2024'!$1:$7

Sheet SUM
C1: <- Click 1 for standard view, 2 for deep dive
C2: HOTEL MALURI PROFIT & LOSS STATEMENT
C4: SUMMARY | O4: YEAR 2024 | AH4: YEAR 2025 | BA4: YEAR 2026
D6: ACC CODE | E6: 46174 | F6: 45809 | G6: VAR | H6: Q2 2026 | I6: Q2 2025 | J6: VAR | K6: YTD 2026 | L6: YTD 2025 | M6: VAR | O6: 45292 | P6: 45323 | Q6: 45352 | R6: 45383 | S6: 45413 | T6: 45444 | U6: 45474 | V6: 45505 | W6: 45536 | X6: 45566 | Y6: 45597 | Z6: 45627 | AA6: TOTAL | AB6: Q1 2024 | AC6: Q2 2024 | AD6: Q3 2024 | AE6: Q4 2024 | AF6: TOTAL | AH6: 45658 | AI6: 45689 | AJ6: 45717 | AK6: 45748 | AL6: 45778 | AM6: 45809 | AN6: 45839 | AO6: 45870 | AP6: 45901 | AQ6: 45931 | AR6: 45962 | AS6: 45992 | AT6: TOTAL | AU6: Q1 2025 | AV6: Q2 2025 | AW6: Q3 2025 | AX6: Q4 2025 | AY6: TOTAL | BA6: 46023 | BB6: 46054 | BC6: 46082 | BD6: 46113 | BE6: 46143 | BF6: 46174 | BG6: 46204 | BH6: 46235 | BI6: 46266 | BJ6: 46296 | BK6: 46327 | BL6: 46357 | BM6: TOTAL | BN6: Q1 2026 | BO6: Q2 2026 | BP6: Q3 2026 | BQ6: Q4 2026 | BR6: TOTAL
C8: ROOM STATS
C10: ROOMS AVAILABLE | E10: =SUMIF($BA$6:$BL$6,$E$6,$BA10:$BL10) -> 4440 | F10: =SUMIF($AH$6:$AS$6,$F$6,$AH10:$AS10) -> 4440 | G10: =(E10-F10)/F10 -> 0 | H10: =SUMIF($BN$6:$BR$6,$H$6,$BN10:$BR10) -> 13468 | I10: =SUMIF($AU$6:$AY$6,$I$6,$AU10:$AY10) -> 17677 | J10: =(H10-I10)/I10 -> -0.23810601 | K10: =BM10 -> 26788 | L10: =SUM(AH10:AM10) -> 37207 | M10: =(K10-L10)/L10 -> -0.28002795 | O10: 6727 | P10: 6293 | Q10: 6727 | R10: 6510 | S10: 6727 | T10: 6510 | U10: 6727 | V10: 6727 | W10: 6510 | X10: 6727 | Y10: 6510 | Z10: 6727 | AA10: =SUM(O10:Z10) -> 79422 | AB10: =SUM(O10:Q10) -> 19747 | AC10: =SUM(R10:T10) -> 19747 | AD10: =SUM(U10:W10) -> 19964 | AE10: =SUM(X10:Z10) -> 19964 | AF10: =SUM(AB10:AE10) -> 79422 | AH10: 6727 | AI10: 6076 | AJ10: 6727 | AK10: 6510 | AL10: 6727 | AM10: 4440 | AN10: 4588 | AO10: 4588 | AP10: 4440 | AQ10: 4588 | AR10: 4440 | AS10: 1 | AT10: =SUM(AH10:AS10) -> 59852 | AU10: =SUM(AH10:AJ10) -> 19530 | AV10: =SUM(AK10:AM10) -> 17677 | AW10: =SUM(AN10:AP10) -> 13616 | AX10: =SUM(AQ10:AS10) -> 9029 | AY10: =SUM(AU10:AX10) -> 59852 | BA10: 4588 | BB10: 4144 | BC10: 4588 | BD10: ='2026'!H10 -> 4440 | BE10: ='2026'!I10 -> 4588 | BF10: ='2026'!J10 -> 4440 | BG10: ='2026'!K10 -> 0 | BH10: ='2026'!L10 -> 0 | BI10: ='2026'!M10 -> 0 | BJ10: ='2026'!N10 -> 0 | BK10: ='2026'!O10 -> 0 | BL10: ='2026'!P10 -> 0 | BM10: =SUM(BA10:BL10) -> 26788 | BN10: =SUM(BA10:BC10) -> 13320 | BO10: =SUM(BD10:BF10) -> 13468 | BP10: =SUM(BG10:BI10) -> 0 | BQ10: =SUM(BJ10:BL10) -> 0 | BR10: =SUM(BN10:BQ10) -> 26788
C11: ROOM SOLD | E11: =SUMIF($BA$6:$BL$6,$E$6,$BA11:$BL11) -> 2397 | F11: =SUMIF($AH$6:$AS$6,$F$6,$AH11:$AS11) -> 2193 | G11: =(E11-F11)/F11 -> 0.093023256 | H11: =SUMIF($BN$6:$BR$6,$H$6,$BN11:$BR11) -> 7284 | I11: =SUMIF($AU$6:$AY$6,$I$6,$AU11:$AY11) -> 6602 | J11: =(H11-I11)/I11 -> 0.10330203 | K11: =BM11 -> 14363 | L11: =SUM(AH11:AM11) -> 13295 | M11: =(K11-L11)/L11 -> 0.080330951 | O11: 1500 | P11: 2279 | Q11: 1846 | R11: 1665 | S11: 2319 | T11: 2266 | U11: 3006 | V11: 3005 | W11: 2535 | X11: 2460 | Y11: 2538 | Z11: 3117 | AA11: =SUM(O11:Z11) -> 28536 | AB11: =SUM(O11:Q11) -> 5625 | AC11: =SUM(R11:T11) -> 6250 | AD11: =SUM(U11:W11) -> 8546 | AE11: =SUM(X11:Z11) -> 8115 | AF11: =SUM(AB11:AE11) -> 28536 | AH11: 2536 | AI11: 2433 | AJ11: 1724 | AK11: 2143 | AL11: 2266 | AM11: 2193 | AN11: 2158 | AO11: 2340 | AP11: 2147 | AQ11: 1646 | AR11: 1746 | AS11: 1 | AT11: =SUM(AH11:AS11) -> 23333 | AU11: =SUM(AH11:AJ11) -> 6693 | AV11: =SUM(AK11:AM11) -> 6602 | AW11: =SUM(AN11:AP11) -> 6645 | AX11: =SUM(AQ11:AS11) -> 3393 | AY11: =SUM(AU11:AX11) -> 23333 | BA11: 2681 | BB11: 2313 | BC11: 2085 | BD11: ='2026'!H11 -> 2418 | BE11: ='2026'!I11 -> 2469 | BF11: ='2026'!J11 -> 2397 | BG11: ='2026'!K11 -> 0 | BH11: ='2026'!L11 -> 0 | BI11: ='2026'!M11 -> 0 | BJ11: ='2026'!N11 -> 0 | BK11: ='2026'!O11 -> 0 | BL11: ='2026'!P11 -> 0 | BM11: =SUM(BA11:BL11) -> 14363 | BN11: =SUM(BA11:BC11) -> 7079 | BO11: =SUM(BD11:BF11) -> 7284 | BP11: =SUM(BG11:BI11) -> 0 | BQ11: =SUM(BJ11:BL11) -> 0 | BR11: =SUM(BN11:BQ11) -> 14363
C12: OCCUPANCY % | E12: =SUMIF($BA$6:$BL$6,$E$6,$BA12:$BL12) -> 0.53986486 | F12: =SUMIF($AH$6:$AS$6,$F$6,$AH12:$AS12) -> 0.49391892 | G12: =(E12-F12)/F12 -> 0.093023256 | H12: =SUMIF($BN$6:$BR$6,$H$6,$BN12:$BR12) -> 0.54083754 | I12: =SUMIF($AU$6:$AY$6,$I$6,$AU12:$AY12) -> 0.37347966 | J12: =(H12-I12)/I12 -> 0.44810439 | K12: =BM12 -> 0.53617291 | L12: =L11/L10 -> 0.35732523 | M12: =(K12-L12)/L12 -> 0.50051791 | O12: =O11/O10 -> 0.22298201 | P12: =P11/P10 -> 0.36214842 | Q12: =Q11/Q10 -> 0.27441653 | R12: =R11/R10 -> 0.25576037 | S12: =S11/S10 -> 0.34473019 | T12: =T11/T10 -> 0.34807988 | U12: =U11/U10 -> 0.44685595 | V12: =V11/V10 -> 0.4467073 | ... Z12: =Z11/Z10 -> 0.46335662 | AA12: =SUM(O12:Z12) -> 4.3099904 | AB12: =AB11/AB10 -> 0.2848534 | AC12: =AC11/AC10 -> 0.31650377 | AD12: =AD11/AD10 -> 0.42807053 | AE12: =AE11/AE10 -> 0.40648167 | AF12: =AF11/AF10 -> 0.35929591 | AH12: =AH11/AH10 -> 0.37698826 | AI12: =AI11/AI10 -> 0.40042791 | AJ12: =AJ11/AJ10 -> 0.25628066 | AK12: =AK11/AK10 -> 0.32918587 | AL12: =AL11/AL10 -> 0.33685149 | AM12: =AM11/AM10 -> 0.49391892 | AN12: =AN11/AN10 -> 0.47035745 | AO12: =AO11/AO10 -> 0.51002616 | ... AS12: =AS11/AS10 -> 1 | AT12: =SUM(AH12:AS12) -> 5.4096005 | AU12: =AU11/AU10 -> 0.34270353 | AV12: =AV11/AV10 -> 0.37347966 | AW12: =AW11/AW10 -> 0.48802879 | AX12: =AX11/AX10 -> 0.37578912 | AY12: =AY11/AY10 -> 0.38984495 | BA12: =BA11/BA10 -> 0.58435048 | BB12: =BB11/BB10 -> 0.55815637 | BC12: =BC11/BC10 -> 0.45444638 | BD12: ='2026'!H12 -> 0.54459459 | BE12: ='2026'!I12 -> 0.53814298 | BF12: ='2026'!J12 -> 0.53986486 | BG12: ='2026'!K12 -> 0 | BH12: ='2026'!L12 -> 0 | BI12: ='2026'!M12 -> 0 | BJ12: ='2026'!N12 -> 0 | BK12: ='2026'!O12 -> 0 | BL12: ='2026'!P12 -> 0 | BM12: =BM11/BM10 -> 0.53617291 | BN12: =BN11/BN10 -> 0.53145646 | BO12: =BO11/BO10 -> 0.54083754 | BR12: =BR11/BR10 -> 0.53617291
C13: AVERAGE RATE | E13: =SUMIF($BA$6:$BL$6,$E$6,$BA13:$BL13) -> 153.36213 | F13: =SUMIF($AH$6:$AS$6,$F$6,$AH13:$AS13) -> 147.00023 | G13: =(E13-F13)/F13 -> 0.04327819 | H13: =SUMIF($BN$6:$BR$6,$H$6,$BN13:$BR13) -> 466.64773 | I13: =SUMIF($AU$6:$AY$6,$I$6,$AU13:$AY13) -> 440.69976 | J13: =(H13-I13)/I13 -> 0.058879016 | K13: =BM13 -> 938.38147 | L13: =SUM(AH13:AM13) -> 882.6377 | M13: =(K13-L13)/L13 -> 0.063155889 | O13: 132.20001 | P13: 135.93266 | Q13: 140.73536 | R13: 139.35417 | S13: 142.53889 | T13: 139.04339 | U13: 137.75687 | V13: 137.87402 | W13: 143.76785 | X13: 140.60951 | Y13: 140.50317 | Z13: 153.24232 | AA13: =SUM(O13:Z13) -> 1683.5582 | AB13: =SUM(O13:Q13) -> 408.86803 | AC13: =SUM(R13:T13) -> 420.93645 | AD13: =SUM(U13:W13) -> 419.39873 | AE13: =SUM(X13:Z13) -> 434.355 | AF13: =SUM(AB13:AE13) -> 1683.5582 | AH13: =SUM(AH28:AH29)/AH11 -> 148.26769 | AI13: =SUM(AI28:AI29)/AI11 -> 148.44627 | AJ13: =SUM(AJ28:AJ29)/AJ11 -> 145.22398 | AK13: =SUM(AK28:AK29)/AK11 -> 146.0393 | AL13: =SUM(AL28:AL29)/AL11 -> 147.66023 | AM13: =SUM(AM28:AM29)/AM11 -> 147.00023 | AN13: =SUM(AN28:AN29)/AN11 -> 144.92735 | AO13: =SUM(AO28:AO29)/AO11 -> 150.91782 | ... AS13: =SUM(AS28:AS29)/AS11 -> 460827.59 | AT13: =SUM(AH13:AS13) -> 462456.63 | AU13: =SUM(AH13:AJ13) -> 441.93794 | AV13: =SUM(AK13:AM13) -> 440.69976 | AW13: =SUM(AN13:AP13) -> 451.16672 | AX13: =SUM(AQ13:AS13) -> 461122.82 | AY13: =SUM(AU13:AX13) -> 462456.63 | BA13: =SUM(BA28:BA29)/BA11 -> 157.11885 | BB13: =SUM(BB28:BB29)/BB11 -> 160.27401 | BC13: =SUM(BC28:BC29)/BC11 -> 154.34088 | BD13: ='2026'!H13 -> 152.50555 | BE13: ='2026'!I13 -> 160.78005 | BF13: ='2026'!J13 -> 153.36213 | BG13: ='2026'!K13 -> 0 | BH13: ='2026'!L13 -> 0 | BI13: ='2026'!M13 -> 0 | BJ13: ='2026'!N13 -> 0 | BK13: ='2026'!O13 -> 0 | BL13: ='2026'!P13 -> 0 | BM13: =SUM(BA13:BL13) -> 938.38147 | BN13: =SUM(BA13:BC13) -> 471.73374 | BO13: =SUM(BD13:BF13) -> 466.64773 | BP13: =SUM(BG13:BI13) -> 0 | BQ13: =SUM(BJ13:BL13) -> 0 | BR13: =SUM(BN13:BQ13) -> 938.38147
C14: REV PAR | E14: =SUMIF($BA$6:$BL$6,$E$6,$BA14:$BL14) -> 82.794827 | F14: =SUMIF($AH$6:$AS$6,$F$6,$AH14:$AS14) -> 72.606194 | G14: =(E14-F14)/F14 -> 0.14032732 | H14: =SUMIF($BN$6:$BR$6,$H$6,$BN14:$BR14) -> 252.37118 | I14: =SUMIF($AU$6:$AY$6,$I$6,$AU14:$AY14) -> 170.41984 | J14: =(H14-I14)/I14 -> 0.48087912 | K14: =BM14 -> 503.78127 | L14: =SUM(AH14:AM14) -> 322.97514 | M14: =(K14-L14)/L14 -> 0.55981437 | O14: 29.478224 | P14: 49.227799 | Q14: 38.620109 | R14: 35.641275 | S14: 49.137458 | T14: 48.398206 | U14: 61.557477 | V14: 61.58933 | W14: 55.983332 | X14: 51.419563 | Y14: 54.776813 | Z14: 71.005844 | AA14: =SUM(O14:Z14) -> 606.83543 | AB14: =SUM(O14:Q14) -> 117.32613 | AC14: =SUM(R14:T14) -> 133.17694 | AD14: =SUM(U14:W14) -> 179.13014 | AE14: =SUM(X14:Z14) -> 177.20222 | AF14: =SUM(AB14:AE14) -> 606.83543 | AH14: =(AH11/AH10)*AH13 -> 55.895179 | AI14: =(AI11/AI10)*AI13 -> 59.442029 | AJ14: =(AJ11/AJ10)*AJ13 -> 37.218097 | AK14: =(AK11/AK10)*AK13 -> 48.074075 | AL14: =(AL11/AL10)*AL13 -> 49.739569 | AM14: =(AM11/AM10)*AM13 -> 72.606194 | AN14: =(AN11/AN10)*AN13 -> 68.167661 | AO14: =(AO11/AO10)*AO13 -> 76.972036 | ... AS14: =(AS11/AS10)*AS13 -> 460827.59 | AT14: =SUM(AH14:AS14) -> 461481.9 | AU14: =SUM(AH14:AJ14) -> 152.55531 | AV14: =SUM(AK14:AM14) -> 170.41984 | AW14: =SUM(AN14:AP14) -> 220.24676 | AX14: =SUM(AQ14:AS14) -> 460938.68 | AY14: =SUM(AU14:AX14) -> 461481.9 | BA14: =(BA11/BA10)*BA13 -> 91.812476 | BB14: =(BB11/BB10)*BB13 -> 89.457961 | BC14: =(BC11/BC10)*BC13 -> 70.139653 | BD14: ='2026'!H14 -> 83.053696 | BE14: ='2026'!I14 -> 86.522657 | BF14: ='2026'!J14 -> 82.794827 | BG14: ='2026'!K14 -> 0 | BH14: ='2026'!L14 -> 0 | BI14: ='2026'!M14 -> 0 | BJ14: ='2026'!N14 -> 0 | BK14: ='2026'!O14 -> 0 | BL14: ='2026'!P14 -> 0 | BM14: =SUM(BA14:BL14) -> 503.78127 | BN14: =SUM(BA14:BC14) -> 251.41009 | BO14: =SUM(BD14:BF14) -> 252.37118 | BP14: =SUM(BG14:BI14) -> 0 | BQ14: =SUM(BJ14:BL14) -> 0 | BR14: =SUM(BN14:BQ14) -> 503.78127
AB15: =SUM(O15:Q15) -> 0 | AC15: =SUM(R15:T15) -> 0 | AD15: =SUM(U15:W15) -> 0 | AE15: =SUM(X15:Z15) -> 0 | AU15: =SUM(AH15:AJ15) -> 0 | AV15: =SUM(AK15:AM15) -> 0 | AW15: =SUM(AN15:AP15) -> 0 | AX15: =SUM(AQ15:AS15) -> 0 | BN15: =SUM(BA15:BC15) -> 0 | BO15: =SUM(BD15:BF15) -> 0 | BP15: =SUM(BG15:BI15) -> 0 | BQ15: =SUM(BJ15:BL15) -> 0
C16: TOTAL COST | E16: =E108+E221 -> 587454.79 | F16: =F108+F221 -> 459903.73 | G16: =(E16-F16)/F16 -> 0.27734296 | H16: =H108+H221 -> 1747555 | I16: =I108+I221 -> 1431383.3 | J16: =(H16-I16)/I16 -> 0.22088541 | K16: =BM16 -> 3760105.2 | L16: =SUM(AH16:AM16) -> 3130998.7 | M16: =(K16-L16)/L16 -> 0.20092836 | O16: =O108+O221 -> 644636.49 | P16: =P108+P221 -> 483942.81 | Q16: =Q108+Q221 -> 586857.15 | R16: =R108+R221 -> 494401 | S16: =S108+S221 -> 563988.36 | T16: =T108+T221 -> 531323.95 | U16: =U108+U221 -> 767245.55 | V16: =V108+V221 -> 690800.38 | ... Z16: =Z108+Z221 -> 575262.78 | AA16: =SUM(O16:Z16) -> 6937772.6 | AB16: =SUM(O16:Q16) -> 1715436.4 | AC16: =SUM(R16:T16) -> 1589713.3 | AD16: =SUM(U16:W16) -> 1982141.9 | AE16: =SUM(X16:Z16) -> 1650481 | AF16: =SUM(AB16:AE16) -> 6937772.7 | AH16: =AH108+AH221 -> 682120.09 | AI16: =AI108+AI221 -> 513180.3 | AJ16: =AJ108+AJ221 -> 504315 | AK16: =AK108+AK221 -> 458222.32 | AL16: =AL108+AL221 -> 513257.28 | AM16: =AM108+AM221 -> 459903.73 | AN16: =AN108+AN221 -> 472504.77 | AO16: =AO108+AO221 -> 786386.7 | ... AS16: =AS108+AS221 -> 1638506.3 | AT16: =SUM(AH16:AS16) -> 7501944.3 | AU16: =SUM(AH16:AJ16) -> 1699615.4 | AV16: =SUM(AK16:AM16) -> 1431383.3 | AW16: =SUM(AN16:AP16) -> 1758521.9 | AX16: =SUM(AQ16:AS16) -> 2612423.7 | AY16: =SUM(AU16:AX16) -> 7501944.3 | BA16: =BA108+BA221 -> 704693.07 | BB16: =BB108+BB221 -> 642668.4 | BC16: =BC108+BC221 -> 665188.67 | BD16: =BD108+BD221 -> 572560.52 | BE16: =BE108+BE221 -> 587539.72 | BF16: =BF108+BF221 -> 587454.79 | BG16: =BG108+BG221 -> 0 | BH16: =BH108+BH221 -> 0 | ... BL16: =BL108+BL221 -> 0 | BM16: =SUM(BA16:BL16) -> 3760105.2 | BN16: =SUM(BA16:BC16) -> 2012550.1 | BO16: =SUM(BD16:BF16) -> 1747555 | BP16: =SUM(BG16:BI16) -> 0 | BQ16: =SUM(BJ16:BL16) -> 0 | BR16: =SUM(BN16:BQ16) -> 3760105.2
C17: AVERAGE COST | E17: =E16/1 -> 587454.79 | F17: =F16/1 -> 459903.73 | G17: =(E17-F17)/F17 -> 0.27734296 | H17: =H16/3 -> 582518.34 | I17: =I16/3 -> 477127.78 | J17: =(H17-I17)/I17 -> 0.22088541 | K17: =K16/MONTH(E$6) -> 626684.19 | L17: =L16/MONTH(E6) -> 521833.12 | M17: =(K17-L17)/L17 -> 0.20092836 | O17: =O16/1 -> 644636.49 | P17: =P16/1 -> 483942.81 | Q17: =Q16/1 -> 586857.15 | R17: =R16/1 -> 494401 | S17: =S16/1 -> 563988.36 | T17: =T16/1 -> 531323.95 | U17: =U16/1 -> 767245.55 | V17: =V16/1 -> 690800.38 | ... Z17: =Z16/1 -> 575262.78 | AA17: =SUM(O17:Z17) -> 6937772.6 | AB17: =SUM(O17:Q17) -> 1715436.4 | AC17: =SUM(R17:T17) -> 1589713.3 | AD17: =SUM(U17:W17) -> 1982141.9 | AE17: =SUM(X17:Z17) -> 1650481 | AF17: =SUM(AB17:AE17) -> 6937772.7 | AH17: =AH16/1 -> 682120.09 | AI17: =AI16/1 -> 513180.3 | AJ17: =AJ16/1 -> 504315 | AK17: =AK16/1 -> 458222.32 | AL17: =AL16/1 -> 513257.28 | AM17: =AM16/1 -> 459903.73 | AN17: =AN16/1 -> 472504.77 | AO17: =AO16/1 -> 786386.7 | ... AS17: =AS16/1 -> 1638506.3 | AT17: =SUM(AH17:AS17) -> 7501944.3 | AU17: =SUM(AH17:AJ17) -> 1699615.4 | AV17: =SUM(AK17:AM17) -> 1431383.3 | AW17: =SUM(AN17:AP17) -> 1758521.9 | AX17: =SUM(AQ17:AS17) -> 2612423.7 | AY17: =SUM(AU17:AX17) -> 7501944.3 | BA17: =BA16/1 -> 704693.07 | BB17: =BB16/1 -> 642668.4 | BC17: =BC16/1 -> 665188.67 | BD17: =BD16/1 -> 572560.52 | BE17: =BE16/1 -> 587539.72 | BF17: =BF16/1 -> 587454.79 | BG17: =BG16/1 -> 0 | BH17: =BH16/1 -> 0 | ... BL17: =BL16/1 -> 0 | BM17: =SUM(BA17:BL17) -> 3760105.2 | BN17: =SUM(BA17:BC17) -> 2012550.1 | BO17: =SUM(BD17:BF17) -> 1747555 | BP17: =SUM(BG17:BI17) -> 0 | BQ17: =SUM(BJ17:BL17) -> 0 | BR17: =SUM(BN17:BQ17) -> 3760105.2
C19: FOOD REVENUE & COST
C20: FOOD REVENUE * | E20: =E39+E41+E43+E47 -> 47107.01 | F20: =F39+F41+F43+F47 -> 12236.47 | G20: =(E20-F20)/F20 -> 2.8497222 | H20: =H39+H41+H43+H47 -> 125044.17 | I20: =I39+I41+I43+I47 -> 49885.46 | J20: =(H20-I20)/I20 -> 1.5066256 | K20: =K39+K41+K43+K47 -> 361852.24 | L20: =SUM(AH20:AM20) -> 245457.27 | M20: =(K20-L20)/L20 -> 0.47419647 | O20: =O39+O41+O43+O47 -> 25359.38 | P20: =P39+P41+P43+P47 -> 28424.25 | Q20: =Q39+Q41+Q43+Q47 -> 97945.96 | R20: =R39+R41+R43+R47 -> 70797.07 | S20: =S39+S41+S43+S47 -> 33305.83 | T20: =T39+T41+T43+T47 -> 29357.49 | U20: =U39+U41+U43+U47 -> 36166 | V20: =V39+V41+V43+V47 -> 33224.16 | ... Z20: =Z39+Z41+Z43+Z47 -> 19440.23 | AA20: =SUM(O20:Z20) -> 421190.4 | AB20: =SUM(O20:Q20) -> 151729.59 | AC20: =SUM(R20:T20) -> 133460.39 | AD20: =SUM(U20:W20) -> 89795.43 | AE20: =SUM(X20:Z20) -> 46204.99 | AF20: =SUM(AB20:AE20) -> 421190.4 | AH20: =AH39+AH41+AH43+AH47 -> 11237.62 | AI20: =AI39+AI41+AI43+AI47 -> 11051.17 | AJ20: =AJ39+AJ41+AJ43+AJ47 -> 173283.02 | AK20: =AK39+AK41+AK43+AK47 -> 22433.86 | AL20: =AL39+AL41+AL43+AL47 -> 15215.13 | AM20: =AM39+AM41+AM43+AM47 -> 12236.47 | AN20: =AN39+AN41+AN43+AN47 -> 13176.76 | AO20: =AO39+AO41+AO43+AO47 -> 12812.24 | ... AS20: =AS39+AS41+AS43+AS47 -> 15761.74 | AT20: =SUM(AH20:AS20) -> 322508.96 | AU20: =SUM(AH20:AJ20) -> 195571.81 | AV20: =SUM(AK20:AM20) -> 49885.46 | AW20: =SUM(AN20:AP20) -> 38989.86 | AX20: =SUM(AQ20:AS20) -> 38061.83 | AY20: =SUM(AU20:AX20) -> 322508.96 | BA20: =BA39+BA41+BA43+BA47 -> 42929.69 | BB20: =BB39+BB41+BB43+BB47 -> 48662.33 | BC20: =BC39+BC41+BC43+BC47 -> 145216.05 | BD20: =BD39+BD41+BD43+BD47 -> 45729.39 | BE20: =BE39+BE41+BE43+BE47 -> 32207.77 | BF20: =BF39+BF41+BF43+BF47 -> 47107.01 | BG20: =BG39+BG41+BG43+BG47 -> 0 | BH20: =BH39+BH41+BH43+BH47 -> 0 | ... BL20: =BL39+BL41+BL43+BL47 -> 0 | BM20: =SUM(BA20:BL20) -> 361852.24 | BN20: =SUM(BA20:BC20) -> 236808.07 | BO20: =SUM(BD20:BF20) -> 125044.17 | BP20: =SUM(BG20:BI20) -> 0 | BQ20: =SUM(BJ20:BL20) -> 0 | BR20: =SUM(BN20:BQ20) -> 361852.24
C21: FOOD COST ** | E21: =E83+E88+E89+E90+E91+E84 -> 28254.21 | F21: =F83+F88+F89+F90+F91+F84 -> 26128.44 | G21: =(E21-F21)/F21 -> 0.081358474 | H21: =H83+H88+H89+H90+H91+H84 -> 84029.9 | I21: =I83+I88+I89+I90+I91+I84 -> 109850.48 | J21: =(H21-I21)/I21 -> -0.23505205 | K21: =K83+K88+K89+K90+K91+K84 -> 221771.06 | L21: =SUM(AH21:AM21) -> 279534.67 | M21: =(K21-L21)/L21 -> -0.20664202 | O21: =O83+O88+O89+O90+O91+O84 -> 42651.26 | P21: =P83+P88+P89+P90+P91+P84 -> 46548.98 | Q21: =Q83+Q88+Q89+Q90+Q91+Q84 -> 80476.09 | R21: =R83+R88+R89+R90+R91+R84 -> 53120.16 | S21: =S83+S88+S89+S90+S91+S84 -> 53325.88 | T21: =T83+T88+T89+T90+T91+T84 -> 36857.89 | U21: =U83+U88+U89+U90+U91+U84 -> 36605.5 | V21: =V83+V88+V89+V90+V91+V84 -> 50435.96 | ... Z21: =Z83+Z88+Z89+Z90+Z91+Z84 -> 37793.32 | AA21: =SUM(O21:Z21) -> 572962.43 | AB21: =SUM(O21:Q21) -> 169676.33 | AC21: =SUM(R21:T21) -> 143303.93 | AD21: =SUM(U21:W21) -> 124790.29 | AE21: =SUM(X21:Z21) -> 135191.88 | AF21: =SUM(AB21:AE21) -> 572962.43 | AH21: =AH83+AH88+AH89+AH90+AH91+AH84 -> 52439.34 | AI21: =AI83+AI88+AI89+AI90+AI91+AI84 -> 32245.88 | AJ21: =AJ83+AJ88+AJ89+AJ90+AJ91+AJ84 -> 84998.97 | AK21: =AK83+AK88+AK89+AK90+AK91+AK84 -> 32431.83 | AL21: =AL83+AL88+AL89+AL90+AL91+AL84 -> 51290.21 | AM21: =AM83+AM88+AM89+AM90+AM91+AM84 -> 26128.44 | AN21: =AN83+AN88+AN89+AN90+AN91+AN84 -> 32072.54 | AO21: =AO83+AO88+AO89+AO90+AO91+AO84 -> 33955.25 | ... AS21: =AS83+AS88+AS89+AS90+AS91+AS84 -> 44903.05 | AT21: =SUM(AH21:AS21) -> 499535.26 | AU21: =SUM(AH21:AJ21) -> 169684.19 | AV21: =SUM(AK21:AM21) -> 109850.48 | AW21: =SUM(AN21:AP21) -> 107824.96 | AX21: =SUM(AQ21:AS21) -> 112175.63 | AY21: =SUM(AU21:AX21) -> 499535.26 | BA21: =BA83+BA88+BA89+BA90+BA91+BA84 -> 36014.3 | BB21: =BB83+BB88+BB89+BB90+BB91+BB84 -> 50142.15 | BC21: =BC83+BC88+BC89+BC90+BC91+BC84 -> 51584.71 | BD21: =BD83+BD88+BD89+BD90+BD91+BD84 -> 32936.58 | BE21: =BE83+BE88+BE89+BE90+BE91+BE84 -> 22839.11 | BF21: =BF83+BF88+BF89+BF90+BF91+BF84 -> 28254.21 | BG21: =BG83+BG88+BG89+BG90+BG91+BG84 -> 0 | BH21: =BH83+BH88+BH89+BH90+BH91+BH84 -> 0 | ... BL21: =BL83+BL88+BL89+BL90+BL91+BL84 -> 0 | BM21: =SUM(BA21:BL21) -> 221771.06 | BN21: =SUM(BA21:BC21) -> 137741.16 | BO21: =SUM(BD21:BF21) -> 84029.9 | BP21: =SUM(BG21:BI21) -> 0 | BQ21: =SUM(BJ21:BL21) -> 0 | BR21: =SUM(BN21:BQ21) -> 221771.06
C22: DIFFERENCE | E22: =E20-E21 -> 18852.8 | F22: =F20-F21 -> -13891.97 | G22: =(E22-F22)/F22 -> -2.3571005 | H22: =H20-H21 -> 41014.27 | I22: =I20-I21 -> -59965.02 | J22: =(H22-I22)/I22 -> -1.6839699 | K22: =K20-K21 -> 140081.18 | L22: =L20-L21 -> -34077.4 | M22: =(K22-L22)/L22 -> -5.1106769 | O22: =O20-O21 -> -17291.88 | P22: =P20-P21 -> -18124.73 | Q22: =Q20-Q21 -> 17469.87 | R22: =R20-R21 -> 17676.91 | S22: =S20-S21 -> -20020.05 | T22: =T20-T21 -> -7500.4 | U22: =U20-U21 -> -439.5 | V22: =V20-V21 -> -17211.8 | ... Z22: =Z20-Z21 -> -18353.09 | AA22: =SUM(O22:Z22) -> -151772.03 | AB22: =SUM(O22:Q22) -> -17946.74 | AC22: =SUM(R22:T22) -> -9843.54 | AD22: =SUM(U22:W22) -> -34994.86 | AE22: =SUM(X22:Z22) -> -88986.89 | AF22: =SUM(AB22:AE22) -> -151772.03 | AH22: =AH20-AH21 -> -41201.72 | AI22: =AI20-AI21 -> -21194.71 | AJ22: =AJ20-AJ21 -> 88284.05 | AK22: =AK20-AK21 -> -9997.97 | AL22: =AL20-AL21 -> -36075.08 | AM22: =AM20-AM21 -> -13891.97 | AN22: =AN20-AN21 -> -18895.78 | AO22: =AO20-AO21 -> -21143.01 | ... AS22: =AS20-AS21 -> -29141.31 | AT22: =SUM(AH22:AS22) -> -177026.3 | AU22: =SUM(AH22:AJ22) -> 25887.62 | AV22: =SUM(AK22:AM22) -> -59965.02 | AW22: =SUM(AN22:AP22) -> -68835.1 | AX22: =SUM(AQ22:AS22) -> -74113.8 | AY22: =SUM(AU22:AX22) -> -177026.3 | BA22: =BA20-BA21 -> 6915.39 | BB22: =BB20-BB21 -> -1479.82 | BC22: =BC20-BC21 -> 93631.34 | BD22: =BD20-BD21 -> 12792.81 | BE22: =BE20-BE21 -> 9368.66 | BF22: =BF20-BF21 -> 18852.8 | BG22: =BG20-BG21 -> 0 | BH22: =BH20-BH21 -> 0 | ... BL22: =BL20-BL21 -> 0 | BM22: =SUM(BA22:BL22) -> 140081.18 | BN22: =SUM(BA22:BC22) -> 99066.91 | BO22: =SUM(BD22:BF22) -> 41014.27 | BP22: =SUM(BG22:BI22) -> 0 | BQ22: =SUM(BJ22:BL22) -> 0 | BR22: =SUM(BN22:BQ22) -> 140081.18
C25: REVENUE | AB25: =SUM(O25:Q25) -> 0 | AC25: =SUM(R25:T25) -> 0 | AD25: =SUM(U25:W25) -> 0 | AE25: =SUM(X25:Z25) -> 0 | AU25: =SUM(AH25:AJ25) -> 0 | AV25: =SUM(AK25:AM25) -> 0 | AW25: =SUM(AN25:AP25) -> 0 | AX25: =SUM(AQ25:AS25) -> 0 | BN25: =SUM(BA25:BC25) -> 0 | BO25: =SUM(BD25:BF25) -> 0 | BP25: =SUM(BG25:BI25) -> 0 | BQ25: =SUM(BJ25:BL25) -> 0
AB26: =SUM(O26:Q26) -> 0 | AC26: =SUM(R26:T26) -> 0 | AD26: =SUM(U26:W26) -> 0 | AE26: =SUM(X26:Z26) -> 0 | AU26: =SUM(AH26:AJ26) -> 0 | AV26: =SUM(AK26:AM26) -> 0 | AW26: =SUM(AN26:AP26) -> 0 | AX26: =SUM(AQ26:AS26) -> 0 | BN26: =SUM(BA26:BC26) -> 0 | BO26: =SUM(BD26:BF26) -> 0 | BP26: =SUM(BG26:BI26) -> 0 | BQ26: =SUM(BJ26:BL26) -> 0
A27: ROOM | B27: 500-1000 | C27: ROOM | D27: 500-1000 | E27: =SUMIF($BA$6:$BL$6,$E$6,$BA27:$BL27) -> 380114.73 | F27: =SUMIF($AH$6:$AS$6,$F$6,$AH27:$AS27) -> 336619.46 | G27: =(E27-F27)/F27 -> 0.12921199 | H27: =SUMIF($BN$6:$BR$6,$H$6,$BN27:$BR27) -> 1171257.7 | I27: =SUMIF($AU$6:$AY$6,$I$6,$AU27:$AY27) -> 1014736.5 | J27: =(H27-I27)/I27 -> 0.15424812 | K27: =BM27 -> 2322249.5 | L27: =SUM(AH27:AM27) -> 2029522.1 | M27: =(K27-L27)/L27 -> 0.14423464 | O27: =SUMIF('2024 AC'!$B$3:$B$250,"*"&$D27&"*",'2024 AC'!C$3:C$250) -> 215086.38 | P27: =SUMIF('2024 AC'!$B$3:$B$250,"*"&$D27&"*",'2024 AC'!D$3:D$250) -> 330522.99 | Q27: =SUMIF('2024 AC'!$B$3:$B$250,"*"&$D27&"*",'2024 AC'!E$3:E$250) -> 267347.64 | R27: =SUMIF('2024 AC'!$B$3:$B$250,"*"&$D27&"*",'2024 AC'!F$3:F$250) -> 242849.09 | S27: =SUMIF('2024 AC'!$B$3:$B$250,"*"&$D27&"*",'2024 AC'!G$3:G$250) -> 349112.36 | T27: =SUMIF('2024 AC'!$B$3:$B$250,"*"&$D27&"*",'2024 AC'!H$3:H$250) -> 329037.23 | U27: =SUMIF('2024 AC'!$B$3:$B$250,"*"&$D27&"*",'2024 AC'!I$3:I$250) -> 430480.72 | V27: =SUMIF('2024 AC'!$B$3:$B$250,"*"&$D27&"*",'2024 AC'!J$3:J$250) -> 440278.28 | ... Z27: =SUMIF('2024 AC'!$B$3:$B$250,"*"&$D27&"*",'2024 AC'!N$3:N$250) -> 489138.54 | AA27: =SUM(O27:Z27) -> 4210071.2 | AB27: =SUM(O27:Q27) -> 812957.01 | AC27: =SUM(R27:T27) -> 920998.68 | AD27: =SUM(U27:W27) -> 1247848.6 | AE27: =SUM(X27:Z27) -> 1228266.9 | AF27: =SUM(AB27:AE27) -> 4210071.2 | AH27: =SUMIF('2025 AC'!$B$3:$B$250,"*"&$D27&"*",'2025 AC'!C$3:C$250) -> 387262.17 | AI27: =SUMIF('2025 AC'!$B$3:$B$250,"*"&$D27&"*",'2025 AC'!D$3:D$250) -> 370307.95 | AJ27: =SUMIF('2025 AC'!$B$3:$B$250,"*"&$D27&"*",'2025 AC'!E$3:E$250) -> 257215.41 | AK27: =SUMIF('2025 AC'!$B$3:$B$250,"*"&$D27&"*",'2025 AC'!F$3:F$250) -> 325707.83 | AL27: =SUMIF('2025 AC'!$B$3:$B$250,"*"&$D27&"*",'2025 AC'!G$3:G$250) -> 352409.25 | AM27: =SUMIF('2025 AC'!$B$3:$B$250,"*"&$D27&"*",'2025 AC'!H$3:H$250) -> 336619.46 | AN27: =SUMIF('2025 AC'!$B$3:$B$250,"*"&$D27&"*",'2025 AC'!I$3:I$250) -> 329009.54 | AO27: =SUMIF('2025 AC'!$B$3:$B$250,"*"&$D27&"*",'2025 AC'!J$3:J$250) -> 369440.7 | ... AS27: =SUMIF('2025 AC'!$B$3:$B$250,"*"&$D27&"*",'2025 AC'!N$3:N$250) -> 474032.84 | AT27: =SUM(AH27:AS27) -> 4083024 | AU27: =SUM(AH27:AJ27) -> 1014785.5 | AV27: =SUM(AK27:AM27) -> 1014736.5 | AW27: =SUM(AN27:AP27) -> 1051146.6 | AX27: =SUM(AQ27:AS27) -> 1002355.3 | AY27: =SUM(AU27:AX27) -> 4083024 | BA27: =SUMIF('2026 AC'!$B$3:$B$254,"*"&$D27&"*",'2026 AC'!C$3:C$254) -> 435957.26 | BB27: =SUMIF('2026 AC'!$B$3:$B$254,"*"&$D27&"*",'2026 AC'!D$3:D$254) -> 381267.35 | BC27: =SUMIF('2026 AC'!$B$3:$B$254,"*"&$D27&"*",'2026 AC'!E$3:E$254) -> 333767.1 | BD27: =SUMIF('2026 AC'!$B$3:$B$254,"*"&$D27&"*",'2026 AC'!F$3:F$254) -> 384752.75 | BE27: =SUMIF('2026 AC'!$B$3:$B$254,"*"&$D27&"*",'2026 AC'!G$3:G$254) -> 406390.26 | BF27: =SUMIF('2026 AC'!$B$3:$B$254,"*"&$D27&"*",'2026 AC'!H$3:H$254) -> 380114.73 | BG27: =SUMIF('2026 AC'!$B$3:$B$254,"*"&$D27&"*",'2026 AC'!I$3:I$254) -> 0 | BH27: =SUMIF('2026 AC'!$B$3:$B$254,"*"&$D27&"*",'2026 AC'!J$3:J$254) -> 0 | ... BL27: =SUMIF('2026 AC'!$B$3:$B$254,"*"&$D27&"*",'2026 AC'!N$3:N$254) -> 0 | BM27: =SUM(BA27:BL27) -> 2322249.5 | BN27: =SUM(BA27:BC27) -> 1150991.7 | BO27: =SUM(BD27:BF27) -> 1171257.7 | BP27: =SUM(BG27:BI27) -> 0 | BQ27: =SUM(BJ27:BL27) -> 0 | BR27: =SUM(BN27:BQ27) -> 2322249.5
A28: ROOM CHARGE (SC) | B28: 500-1001 | C28: ROOM CHARGE (SC) | D28: 500-1001 | E28: =SUMIF($BA$6:$BL$6,$E$6,$BA28:$BL28) -> 45375.88 | F28: =SUMIF($AH$6:$AS$6,$F$6,$AH28:$AS28) -> 56019.32 | G28: =(E28-F28)/F28 -> -0.18999588 | H28: =SUMIF($BN$6:$BR$6,$H$6,$BN28:$BR28) -> 150171.45 | I28: =SUMIF($AU$6:$AY$6,$I$6,$AU28:$AY28) -> 152422.71 | J28: =(H28-I28)/I28 -> -0.014769846 | K28: =BM28 -> 311649.44 | L28: =SUM(AH28:AM28) -> 274680.82 | M28: =(K28-L28)/L28 -> 0.13458756 | O28: =SUMIF('2024 AC'!$B$3:$B$250,"*"&$D28&"*",'2024 AC'!C$3:C$250) -> 91824.64 | P28: =SUMIF('2024 AC'!$B$3:$B$250,"*"&$D28&"*",'2024 AC'!D$3:D$250) -> 117113.12 | Q28: =SUMIF('2024 AC'!$B$3:$B$250,"*"&$D28&"*",'2024 AC'!E$3:E$250) -> 39065.6 | R28: =SUMIF('2024 AC'!$B$3:$B$250,"*"&$D28&"*",'2024 AC'!F$3:F$250) -> 49011.14 | S28: =SUMIF('2024 AC'!$B$3:$B$250,"*"&$D28&"*",'2024 AC'!G$3:G$250) -> 56140.47 | T28: =SUMIF('2024 AC'!$B$3:$B$250,"*"&$D28&"*",'2024 AC'!H$3:H$250) -> 53387.22 | U28: =SUMIF('2024 AC'!$B$3:$B$250,"*"&$D28&"*",'2024 AC'!I$3:I$250) -> 99876.81 | V28: =SUMIF('2024 AC'!$B$3:$B$250,"*"&$D28&"*",'2024 AC'!J$3:J$250) -> 94461.36 | ... Z28: =SUMIF('2024 AC'!$B$3:$B$250,"*"&$D28&"*",'2024 AC'!N$3:N$250) -> 41620.43 | AA28: =SUM(O28:Z28) -> 841352.73 | AB28: =SUM(O28:Q28) -> 248003.36 | AC28: =SUM(R28:T28) -> 158538.83 | AD28: =SUM(U28:W28) -> 249172.88 | AE28: =SUM(X28:Z28) -> 185637.66 | AF28: =SUM(AB28:AE28) -> 841352.73 | AH28: =SUMIF('2025 AC'!$B$3:$B$250,"*"&$D28&"*",'2025 AC'!C$3:C$250) -> 36556.07 | AI28: =SUMIF('2025 AC'!$B$3:$B$250,"*"&$D28&"*",'2025 AC'!D$3:D$250) -> 37009.27 | AJ28: =SUMIF('2025 AC'!$B$3:$B$250,"*"&$D28&"*",'2025 AC'!E$3:E$250) -> 48692.77 | AK28: =SUMIF('2025 AC'!$B$3:$B$250,"*"&$D28&"*",'2025 AC'!F$3:F$250) -> 52694.7 | AL28: =SUMIF('2025 AC'!$B$3:$B$250,"*"&$D28&"*",'2025 AC'!G$3:G$250) -> 43708.69 | AM28: =SUMIF('2025 AC'!$B$3:$B$250,"*"&$D28&"*",'2025 AC'!H$3:H$250) -> 56019.32 | AN28: =SUMIF('2025 AC'!$B$3:$B$250,"*"&$D28&"*",'2025 AC'!I$3:I$250) -> 55221.53 | AO28: =SUMIF('2025 AC'!$B$3:$B$250,"*"&$D28&"*",'2025 AC'!J$3:J$250) -> 42610.84 | ... AS28: =SUMIF('2025 AC'!$B$3:$B$250,"*"&$D28&"*",'2025 AC'!N$3:N$250) -> 48222.76 | AT28: =SUM(AH28:AS28) -> 533790.77 | AU28: =SUM(AH28:AJ28) -> 122258.11 | AV28: =SUM(AK28:AM28) -> 152422.71 | AW28: =SUM(AN28:AP28) -> 141207.78 | AX28: =SUM(AQ28:AS28) -> 117902.17 | AY28: =SUM(AU28:AX28) -> 533790.77 | BA28: =SUMIF('2026 AC'!$B$3:$B$254,"*"&$D28&"*",'2026 AC'!C$3:C$254) -> 72341.52 | BB28: =SUMIF('2026 AC'!$B$3:$B$254,"*"&$D28&"*",'2026 AC'!D$3:D$254) -> 41920.27 | BC28: =SUMIF('2026 AC'!$B$3:$B$254,"*"&$D28&"*",'2026 AC'!E$3:E$254) -> 47216.2 | BD28: =SUMIF('2026 AC'!$B$3:$B$254,"*"&$D28&"*",'2026 AC'!F$3:F$254) -> 64930.4 | BE28: =SUMIF('2026 AC'!$B$3:$B$254,"*"&$D28&"*",'2026 AC'!G$3:G$254) -> 39865.17 | BF28: =SUMIF('2026 AC'!$B$3:$B$254,"*"&$D28&"*",'2026 AC'!H$3:H$254) -> 45375.88 | BG28: =SUMIF('2026 AC'!$B$3:$B$254,"*"&$D28&"*",'2026 AC'!I$3:I$254) -> 0 | BH28: =SUMIF('2026 AC'!$B$3:$B$254,"*"&$D28&"*",'2026 AC'!J$3:J$254) -> 0 | ... BL28: =SUMIF('2026 AC'!$B$3:$B$254,"*"&$D28&"*",'2026 AC'!N$3:N$254) -> 0 | BM28: =SUM(BA28:BL28) -> 311649.44 | BN28: =SUM(BA28:BC28) -> 161477.99 | BO28: =SUM(BD28:BF28) -> 150171.45 | BP28: =SUM(BG28:BI28) -> 0 | BQ28: =SUM(BJ28:BL28) -> 0 | BR28: =SUM(BN28:BQ28) -> 311649.44
A29: ROOM CHARGE (NSC) | B29: 500-1002 | C29: ROOM CHARGE (NSC) | D29: 500-1002 | E29: =SUMIF($BA$6:$BL$6,$E$6,$BA29:$BL29) -> 322233.15 | F29: =SUMIF($AH$6:$AS$6,$F$6,$AH29:$AS29) -> 266352.18 | G29: =(E29-F29)/F29 -> 0.20980106 | H29: =SUMIF($BN$6:$BR$6,$H$6,$BN29:$BR29) -> 983161.94 | I29: =SUMIF($AU$6:$AY$6,$I$6,$AU29:$AY29) -> 817509.1 | J29: =(H29-I29)/I29 -> 0.20263119 | K29: =BM29 -> 1935434.1 | L29: =SUM(AH29:AM29) -> 1682793.8 | M29: =(K29-L29)/L29 -> 0.15013149 | O29: =SUMIF('2024 AC'!$B$3:$B$250,"*"&$D29&"*",'2024 AC'!C$3:C$250) -> 106475.37 | P29: =SUMIF('2024 AC'!$B$3:$B$250,"*"&$D29&"*",'2024 AC'!D$3:D$250) -> 192677.42 | Q29: =SUMIF('2024 AC'!$B$3:$B$250,"*"&$D29&"*",'2024 AC'!E$3:E$250) -> 220731.87 | R29: =SUMIF('2024 AC'!$B$3:$B$250,"*"&$D29&"*",'2024 AC'!F$3:F$250) -> 183013.56 | S29: =SUMIF('2024 AC'!$B$3:$B$250,"*"&$D29&"*",'2024 AC'!G$3:G$250) -> 274407.21 | T29: =SUMIF('2024 AC'!$B$3:$B$250,"*"&$D29&"*",'2024 AC'!H$3:H$250) -> 261685.1 | U29: =SUMIF('2024 AC'!$B$3:$B$250,"*"&$D29&"*",'2024 AC'!I$3:I$250) -> 314220.34 | V29: =SUMIF('2024 AC'!$B$3:$B$250,"*"&$D29&"*",'2024 AC'!J$3:J$250) -> 319850.06 | ... Z29: =SUMIF('2024 AC'!$B$3:$B$250,"*"&$D29&"*",'2024 AC'!N$3:N$250) -> 436035.88 | AA29: =SUM(O29:Z29) -> 3177192.8 | AB29: =SUM(O29:Q29) -> 519884.66 | AC29: =SUM(R29:T29) -> 719105.87 | AD29: =SUM(U29:W29) -> 943687.18 | AE29: =SUM(X29:Z29) -> 994515.1 | AF29: =SUM(AB29:AE29) -> 3177192.8 | AH29: =SUMIF('2025 AC'!$B$3:$B$250,"*"&$D29&"*",'2025 AC'!C$3:C$250) -> 339450.8 | AI29: =SUMIF('2025 AC'!$B$3:$B$250,"*"&$D29&"*",'2025 AC'!D$3:D$250) -> 324160.5 | AJ29: =SUMIF('2025 AC'!$B$3:$B$250,"*"&$D29&"*",'2025 AC'!E$3:E$250) -> 201673.37 | AK29: =SUMIF('2025 AC'!$B$3:$B$250,"*"&$D29&"*",'2025 AC'!F$3:F$250) -> 260267.53 | AL29: =SUMIF('2025 AC'!$B$3:$B$250,"*"&$D29&"*",'2025 AC'!G$3:G$250) -> 290889.39 | AM29: =SUMIF('2025 AC'!$B$3:$B$250,"*"&$D29&"*",'2025 AC'!H$3:H$250) -> 266352.18 | AN29: =SUMIF('2025 AC'!$B$3:$B$250,"*"&$D29&"*",'2025 AC'!I$3:I$250) -> 257531.7 | AO29: =SUMIF('2025 AC'!$B$3:$B$250,"*"&$D29&"*",'2025 AC'!J$3:J$250) -> 310536.86 | ... AS29: =SUMIF('2025 AC'!$B$3:$B$250,"*"&$D29&"*",'2025 AC'!N$3:N$250) -> 412604.83 | AT29: =SUM(AH29:AS29) -> 3384841.7 | AU29: =SUM(AH29:AJ29) -> 865284.67 | AV29: =SUM(AK29:AM29) -> 817509.1 | AW29: =SUM(AN29:AP29) -> 858168.51 | AX29: =SUM(AQ29:AS29) -> 843879.4 | AY29: =SUM(AU29:AX29) -> 3384841.7 | BA29: =SUMIF('2026 AC'!$B$3:$B$254,"*"&$D29&"*",'2026 AC'!C$3:C$254) -> 348894.12 | BB29: =SUMIF('2026 AC'!$B$3:$B$254,"*"&$D29&"*",'2026 AC'!D$3:D$254) -> 328793.52 | BC29: =SUMIF('2026 AC'!$B$3:$B$254,"*"&$D29&"*",'2026 AC'!E$3:E$254) -> 274584.53 | BD29: =SUMIF('2026 AC'!$B$3:$B$254,"*"&$D29&"*",'2026 AC'!F$3:F$254) -> 303828.01 | BE29: =SUMIF('2026 AC'!$B$3:$B$254,"*"&$D29&"*",'2026 AC'!G$3:G$254) -> 357100.78 | BF29: =SUMIF('2026 AC'!$B$3:$B$254,"*"&$D29&"*",'2026 AC'!H$3:H$254) -> 322233.15 | BG29: =SUMIF('2026 AC'!$B$3:$B$254,"*"&$D29&"*",'2026 AC'!I$3:I$254) -> 0 | BH29: =SUMIF('2026 AC'!$B$3:$B$254,"*"&$D29&"*",'2026 AC'!J$3:J$254) -> 0 | ... BL29: =SUMIF('2026 AC'!$B$3:$B$254,"*"&$D29&"*",'2026 AC'!N$3:N$254) -> 0 | BM29: =SUM(BA29:BL29) -> 1935434.1 | BN29: =SUM(BA29:BC29) -> 952272.17 | BO29: =SUM(BD29:BF29) -> 983161.94 | BP29: =SUM(BG29:BI29) -> 0 | BQ29: =SUM(BJ29:BL29) -> 0 | BR29: =SUM(BN29:BQ29) -> 1935434.1
A30: ROOM CHARGE - EXTENDED USE | B30: 500-1003 | C30: ROOM CHARGE - EXTRA CHARGES | D30: 500-1003 | E30: =SUMIF($BA$6:$BL$6,$E$6,$BA30:$BL30) -> 1881.4 | F30: =SUMIF($AH$6:$AS$6,$F$6,$AH30:$AS30) -> 0 | G30: =IFERROR((E30-F30)/F30,1) -> 1 | H30: =SUMIF($BN$6:$BR$6,$H$6,$BN30:$BR30) -> 5050.98 | I30: =SUMIF($AU$6:$AY$6,$I$6,$AU30:$AY30) -> 0 | J30: =IFERROR((H30-I30)/I30,1) -> 1 | K30: =BM30 -> 11106.24 | L30: =SUM(AH30:AM30) -> 0 | M30: =IFERROR((K30-L30)/L30,1) -> 1 | O30: =SUMIF('2024 AC'!$B$3:$B$250,"*"&$D30&"*",'2024 AC'!C$3:C$250) -> 0 | P30: =SUMIF('2024 AC'!$B$3:$B$250,"*"&$D30&"*",'2024 AC'!D$3:D$250) -> 0 | Q30: =SUMIF('2024 AC'!$B$3:$B$250,"*"&$D30&"*",'2024 AC'!E$3:E$250) -> 0 | R30: =SUMIF('2024 AC'!$B$3:$B$250,"*"&$D30&"*",'2024 AC'!F$3:F$250) -> 0 | S30: =SUMIF('2024 AC'!$B$3:$B$250,"*"&$D30&"*",'2024 AC'!G$3:G$250) -> 0 | T30: =SUMIF('2024 AC'!$B$3:$B$250,"*"&$D30&"*",'2024 AC'!H$3:H$250) -> 0 | U30: =SUMIF('2024 AC'!$B$3:$B$250,"*"&$D30&"*",'2024 AC'!I$3:I$250) -> 0 | V30: =SUMIF('2024 AC'!$B$3:$B$250,"*"&$D30&"*",'2024 AC'!J$3:J$250) -> 0 | ... Z30: =SUMIF('2024 AC'!$B$3:$B$250,"*"&$D30&"*",'2024 AC'!N$3:N$250) -> 0 | AA30: =SUM(O30:Z30) -> 0 | AB30: =SUM(O30:Q30) -> 0 | AC30: =SUM(R30:T30) -> 0 | AD30: =SUM(U30:W30) -> 0 | AE30: =SUM(X30:Z30) -> 0 | AF30: =SUM(AB30:AE30) -> 0 | AH30: =SUMIF('2025 AC'!$B$3:$B$250,"*"&$D30&"*",'2025 AC'!C$3:C$250) -> 0 | AI30: =SUMIF('2025 AC'!$B$3:$B$250,"*"&$D30&"*",'2025 AC'!D$3:D$250) -> 0 | AJ30: =SUMIF('2025 AC'!$B$3:$B$250,"*"&$D30&"*",'2025 AC'!E$3:E$250) -> 0 | AK30: =SUMIF('2025 AC'!$B$3:$B$250,"*"&$D30&"*",'2025 AC'!F$3:F$250) -> 0 | AL30: =SUMIF('2025 AC'!$B$3:$B$250,"*"&$D30&"*",'2025 AC'!G$3:G$250) -> 0 | AM30: =SUMIF('2025 AC'!$B$3:$B$250,"*"&$D30&"*",'2025 AC'!H$3:H$250) -> 0 | AN30: =SUMIF('2025 AC'!$B$3:$B$250,"*"&$D30&"*",'2025 AC'!I$3:I$250) -> 779.67 | AO30: =SUMIF('2025 AC'!$B$3:$B$250,"*"&$D30&"*",'2025 AC'!J$3:J$250) -> 1432.22 | ... AS30: =SUMIF('2025 AC'!$B$3:$B$250,"*"&$D30&"*",'2025 AC'!N$3:N$250) -> 1258.54 | AT30: =SUM(AH30:AS30) -> 5919.64 | AU30: =SUM(AH30:AJ30) -> 0 | AV30: =SUM(AK30:AM30) -> 0 | AW30: =SUM(AN30:AP30) -> 3211.92 | AX30: =SUM(AQ30:AS30) -> 2707.72 | AY30: =SUM(AU30:AX30) -> 5919.64 | BA30: =SUMIF('2026 AC'!$B$3:$B$254,"*"&$D30&"*",'2026 AC'!C$3:C$254) -> 2122.9 | BB30: =SUMIF('2026 AC'!$B$3:$B$254,"*"&$D30&"*",'2026 AC'!D$3:D$254) -> 1652.62 | BC30: =SUMIF('2026 AC'!$B$3:$B$254,"*"&$D30&"*",'2026 AC'!E$3:E$254) -> 2279.74 | BD30: =SUMIF('2026 AC'!$B$3:$B$254,"*"&$D30&"*",'2026 AC'!F$3:F$254) -> 1355.96 | BE30: =SUMIF('2026 AC'!$B$3:$B$254,"*"&$D30&"*",'2026 AC'!G$3:G$254) -> 1813.62 | BF30: =SUMIF('2026 AC'!$B$3:$B$254,"*"&$D30&"*",'2026 AC'!H$3:H$254) -> 1881.4 | BG30: =SUMIF('2026 AC'!$B$3:$B$254,"*"&$D30&"*",'2026 AC'!I$3:I$254) -> 0 | BH30: =SUMIF('2026 AC'!$B$3:$B$254,"*"&$D30&"*",'2026 AC'!J$3:J$254) -> 0 | ... BL30: =SUMIF('2026 AC'!$B$3:$B$254,"*"&$D30&"*",'2026 AC'!N$3:N$254) -> 0 | BM30: =SUM(BA30:BL30) -> 11106.24 | BN30: =SUM(BA30:BC30) -> 6055.26 | BO30: =SUM(BD30:BF30) -> 5050.98 | BP30: =SUM(BG30:BI30) -> 0 | BQ30: =SUM(BJ30:BL30) -> 0 | BR30: =SUM(BN30:BQ30) -> 11106.24
A31: GUEST SERVICES - LAUNDRY | B31: 500-1004 | C31: GUEST SERVICES - LAUNDRY | D31: 500-1004 | E31: =SUMIF($BA$6:$BL$6,$E$6,$BA31:$BL31) -> 123.01 | F31: =SUMIF($AH$6:$AS$6,$F$6,$AH31:$AS31) -> 0 | G31: =IFERROR((E31-F31)/F31,0) -> 0 | H31: =SUMIF($BN$6:$BR$6,$H$6,$BN31:$BR31) -> 326.82 | I31: =SUMIF($AU$6:$AY$6,$I$6,$AU31:$AY31) -> 108.57 | J31: =IFERROR((H31-I31)/I31,0) -> 2.0102238 | K31: =BM31 -> 813.81 | L31: =SUM(AH31:AM31) -> 108.57 | M31: =IFERROR((K31-L31)/L31,0) -> 6.495717 | O31: =SUMIF('2024 AC'!$B$3:$B$250,"*"&$D31&"*",'2024 AC'!C$3:C$250) -> 0 | P31: =SUMIF('2024 AC'!$B$3:$B$250,"*"&$D31&"*",'2024 AC'!D$3:D$250) -> 0 | Q31: =SUMIF('2024 AC'!$B$3:$B$250,"*"&$D31&"*",'2024 AC'!E$3:E$250) -> 0 | R31: =SUMIF('2024 AC'!$B$3:$B$250,"*"&$D31&"*",'2024 AC'!F$3:F$250) -> 0 | S31: =SUMIF('2024 AC'!$B$3:$B$250,"*"&$D31&"*",'2024 AC'!G$3:G$250) -> 0 | T31: =SUMIF('2024 AC'!$B$3:$B$250,"*"&$D31&"*",'2024 AC'!H$3:H$250) -> 0 | U31: =SUMIF('2024 AC'!$B$3:$B$250,"*"&$D31&"*",'2024 AC'!I$3:I$250) -> 0 | V31: =SUMIF('2024 AC'!$B$3:$B$250,"*"&$D31&"*",'2024 AC'!J$3:J$250) -> 0 | ... Z31: =SUMIF('2024 AC'!$B$3:$B$250,"*"&$D31&"*",'2024 AC'!N$3:N$250) -> 739.75 | AA31: =SUM(O31:Z31) -> 787.25 | AB31: =SUM(O31:Q31) -> 0 | AC31: =SUM(R31:T31) -> 0 | AD31: =SUM(U31:W31) -> 0 | AE31: =SUM(X31:Z31) -> 787.25 | AF31: =SUM(AB31:AE31) -> 787.25 | AH31: =SUMIF('2025 AC'!$B$3:$B$250,"*"&$D31&"*",'2025 AC'!C$3:C$250) -> 0 | AI31: =SUMIF('2025 AC'!$B$3:$B$250,"*"&$D31&"*",'2025 AC'!D$3:D$250) -> 0 | AJ31: =SUMIF('2025 AC'!$B$3:$B$250,"*"&$D31&"*",'2025 AC'!E$3:E$250) -> 0 | AK31: =SUMIF('2025 AC'!$B$3:$B$250,"*"&$D31&"*",'2025 AC'!F$3:F$250) -> 72.04 | AL31: =SUMIF('2025 AC'!$B$3:$B$250,"*"&$D31&"*",'2025 AC'!G$3:G$250) -> 36.53 | AM31: =SUMIF('2025 AC'!$B$3:$B$250,"*"&$D31&"*",'2025 AC'!H$3:H$250) -> 0 | AN31: =SUMIF('2025 AC'!$B$3:$B$250,"*"&$D31&"*",'2025 AC'!I$3:I$250) -> 0 | AO31: =SUMIF('2025 AC'!$B$3:$B$250,"*"&$D31&"*",'2025 AC'!J$3:J$250) -> 142.08 | ... AS31: =SUMIF('2025 AC'!$B$3:$B$250,"*"&$D31&"*",'2025 AC'!N$3:N$250) -> 0 | AT31: =SUM(AH31:AS31) -> 421.67 | AU31: =SUM(AH31:AJ31) -> 0 | AV31: =SUM(AK31:AM31) -> 108.57 | AW31: =SUM(AN31:AP31) -> 266.57 | AX31: =SUM(AQ31:AS31) -> 46.53 | AY31: =SUM(AU31:AX31) -> 421.67 | BA31: =SUMIF('2026 AC'!$B$3:$B$254,"*"&$D31&"*",'2026 AC'!C$3:C$254) -> 308.01 | BB31: =SUMIF('2026 AC'!$B$3:$B$254,"*"&$D31&"*",'2026 AC'!D$3:D$254) -> 178.98 | BC31: =SUMIF('2026 AC'!$B$3:$B$254,"*"&$D31&"*",'2026 AC'!E$3:E$254) -> 0 | BD31: =SUMIF('2026 AC'!$B$3:$B$254,"*"&$D31&"*",'2026 AC'!F$3:F$254) -> 56.82 | BE31: =SUMIF('2026 AC'!$B$3:$B$254,"*"&$D31&"*",'2026 AC'!G$3:G$254) -> 146.99 | BF31: =SUMIF('2026 AC'!$B$3:$B$254,"*"&$D31&"*",'2026 AC'!H$3:H$254) -> 123.01 | BG31: =SUMIF('2026 AC'!$B$3:$B$254,"*"&$D31&"*",'2026 AC'!I$3:I$254) -> 0 | BH31: =SUMIF('2026 AC'!$B$3:$B$254,"*"&$D31&"*",'2026 AC'!J$3:J$254) -> 0 | ... BL31: =SUMIF('2026 AC'!$B$3:$B$254,"*"&$D31&"*",'2026 AC'!N$3:N$254) -> 0 | BM31: =SUM(BA31:BL31) -> 813.81 | BN31: =SUM(BA31:BC31) -> 486.99 | BO31: =SUM(BD31:BF31) -> 326.82 | BP31: =SUM(BG31:BI31) -> 0 | BQ31: =SUM(BJ31:BL31) -> 0 | BR31: =SUM(BN31:BQ31) -> 813.81
A32: GUEST SERVICES - BC / CONVENIENCE STORE | B32: 500-1005 | C32: GUEST SERVICES - BC / CONVENIENCE STORE | D32: 500-1005 | E32: =SUMIF($BA$6:$BL$6,$E$6,$BA32:$BL32) -> 0 | F32: =SUMIF($AH$6:$AS$6,$F$6,$AH32:$AS32) -> 0 | G32: =IFERROR((E32-F32)/F32,0) -> 0 | H32: =SUMIF($BN$6:$BR$6,$H$6,$BN32:$BR32) -> 0 | I32: =SUMIF($AU$6:$AY$6,$I$6,$AU32:$AY32) -> 0 | J32: =IFERROR((H32-I32)/I32,0) -> 0 | K32: =BM32 -> 0 | L32: =SUM(AH32:AM32) -> 0 | M32: =IFERROR((K32-L32)/L32,0) -> 0 | O32: =SUMIF('2024 AC'!$B$3:$B$250,"*"&$D32&"*",'2024 AC'!C$3:C$250) -> 0 | P32: =SUMIF('2024 AC'!$B$3:$B$250,"*"&$D32&"*",'2024 AC'!D$3:D$250) -> 0 | Q32: =SUMIF('2024 AC'!$B$3:$B$250,"*"&$D32&"*",'2024 AC'!E$3:E$250) -> 0 | R32: =SUMIF('2024 AC'!$B$3:$B$250,"*"&$D32&"*",'2024 AC'!F$3:F$250) -> 0 | S32: =SUMIF('2024 AC'!$B$3:$B$250,"*"&$D32&"*",'2024 AC'!G$3:G$250) -> 416.67 | T32: =SUMIF('2024 AC'!$B$3:$B$250,"*"&$D32&"*",'2024 AC'!H$3:H$250) -> 0 | U32: =SUMIF('2024 AC'!$B$3:$B$250,"*"&$D32&"*",'2024 AC'!I$3:I$250) -> 127.12 | V32: =SUMIF('2024 AC'!$B$3:$B$250,"*"&$D32&"*",'2024 AC'!J$3:J$250) -> 127.12 | ... Z32: =SUMIF('2024 AC'!$B$3:$B$250,"*"&$D32&"*",'2024 AC'!N$3:N$250) -> 260.62 | AA32: =SUM(O32:Z32) -> 1061.2 | AB32: =SUM(O32:Q32) -> 0 | AC32: =SUM(R32:T32) -> 416.67 | AD32: =SUM(U32:W32) -> 383.91 | AE32: =SUM(X32:Z32) -> 260.62 | AF32: =SUM(AB32:AE32) -> 1061.2 | AH32: =SUMIF('2025 AC'!$B$3:$B$250,"*"&$D32&"*",'2025 AC'!C$3:C$250) -> 0 | AI32: =SUMIF('2025 AC'!$B$3:$B$250,"*"&$D32&"*",'2025 AC'!D$3:D$250) -> 0 | AJ32: =SUMIF('2025 AC'!$B$3:$B$250,"*"&$D32&"*",'2025 AC'!E$3:E$250) -> 0 | AK32: =SUMIF('2025 AC'!$B$3:$B$250,"*"&$D32&"*",'2025 AC'!F$3:F$250) -> 0 | AL32: =SUMIF('2025 AC'!$B$3:$B$250,"*"&$D32&"*",'2025 AC'!G$3:G$250) -> 0 | AM32: =SUMIF('2025 AC'!$B$3:$B$250,"*"&$D32&"*",'2025 AC'!H$3:H$250) -> 0 | AN32: =SUMIF('2025 AC'!$B$3:$B$250,"*"&$D32&"*",'2025 AC'!I$3:I$250) -> 0 | AO32: =SUMIF('2025 AC'!$B$3:$B$250,"*"&$D32&"*",'2025 AC'!J$3:J$250) -> 0 | ... AS32: =SUMIF('2025 AC'!$B$3:$B$250,"*"&$D32&"*",'2025 AC'!N$3:N$250) -> 0 | AT32: =SUM(AH32:AS32) -> 0 | AU32: =SUM(AH32:AJ32) -> 0 | AV32: =SUM(AK32:AM32) -> 0 | AW32: =SUM(AN32:AP32) -> 0 | AX32: =SUM(AQ32:AS32) -> 0 | AY32: =SUM(AU32:AX32) -> 0 | BA32: =SUMIF('2026 AC'!$B$3:$B$254,"*"&$D32&"*",'2026 AC'!C$3:C$254) -> 0 | BB32: =SUMIF('2026 AC'!$B$3:$B$254,"*"&$D32&"*",'2026 AC'!D$3:D$254) -> 0 | BC32: =SUMIF('2026 AC'!$B$3:$B$254,"*"&$D32&"*",'2026 AC'!E$3:E$254) -> 0 | BD32: =SUMIF('2026 AC'!$B$3:$B$254,"*"&$D32&"*",'2026 AC'!F$3:F$254) -> 0 | BE32: =SUMIF('2026 AC'!$B$3:$B$254,"*"&$D32&"*",'2026 AC'!G$3:G$254) -> 0 | BF32: =SUMIF('2026 AC'!$B$3:$B$254,"*"&$D32&"*",'2026 AC'!H$3:H$254) -> 0 | BG32: =SUMIF('2026 AC'!$B$3:$B$254,"*"&$D32&"*",'2026 AC'!I$3:I$254) -> 0 | BH32: =SUMIF('2026 AC'!$B$3:$B$254,"*"&$D32&"*",'2026 AC'!J$3:J$254) -> 0 | ... BL32: =SUMIF('2026 AC'!$B$3:$B$254,"*"&$D32&"*",'2026 AC'!N$3:N$254) -> 0 | BM32: =SUM(BA32:BL32) -> 0 | BN32: =SUM(BA32:BC32) -> 0 | BO32: =SUM(BD32:BF32) -> 0 | BP32: =SUM(BG32:BI32) -> 0 | BQ32: =SUM(BJ32:BL32) -> 0 | BR32: =SUM(BN32:BQ32) -> 0
A33: GUEST SERVICES - FLOWER / DECORATION | B33: 500-1006 | C33: GUEST SERVICES - FLOWER | D33: 500-1006 | E33: =SUMIF($BA$6:$BL$6,$E$6,$BA33:$BL33) -> 0 | F33: =SUMIF($AH$6:$AS$6,$F$6,$AH33:$AS33) -> 0 | G33: =IFERROR((E33-F33)/F33,0) -> 0 | H33: =SUMIF($BN$6:$BR$6,$H$6,$BN33:$BR33) -> 0 | I33: =SUMIF($AU$6:$AY$6,$I$6,$AU33:$AY33) -> 0 | J33: =IFERROR((H33-I33)/I33,1) -> 1 | K33: =BM33 -> 42.37 | L33: =SUM(AH33:AM33) -> 0 | M33: =IFERROR((K33-L33)/L33,1) -> 1 | O33: =SUMIF('2024 AC'!$B$3:$B$250,"*"&$D33&"*",'2024 AC'!C$3:C$250) -> 232.75 | P33: =SUMIF('2024 AC'!$B$3:$B$250,"*"&$D33&"*",'2024 AC'!D$3:D$250) -> 0 | Q33: =SUMIF('2024 AC'!$B$3:$B$250,"*"&$D33&"*",'2024 AC'!E$3:E$250) -> 0 | R33: =SUMIF('2024 AC'!$B$3:$B$250,"*"&$D33&"*",'2024 AC'!F$3:F$250) -> 0 | S33: =SUMIF('2024 AC'!$B$3:$B$250,"*"&$D33&"*",'2024 AC'!G$3:G$250) -> 0 | T33: =SUMIF('2024 AC'!$B$3:$B$250,"*"&$D33&"*",'2024 AC'!H$3:H$250) -> 0 | U33: =SUMIF('2024 AC'!$B$3:$B$250,"*"&$D33&"*",'2024 AC'!I$3:I$250) -> 0 | V33: =SUMIF('2024 AC'!$B$3:$B$250,"*"&$D33&"*",'2024 AC'!J$3:J$250) -> 0 | ... Z33: =SUMIF('2024 AC'!$B$3:$B$250,"*"&$D33&"*",'2024 AC'!N$3:N$250) -> 0 | AA33: =SUM(O33:Z33) -> 232.75 | AB33: =SUM(O33:Q33) -> 232.75 | AC33: =SUM(R33:T33) -> 0 | AD33: =SUM(U33:W33) -> 0 | AE33: =SUM(X33:Z33) -> 0 | AF33: =SUM(AB33:AE33) -> 232.75 | AH33: =SUMIF('2025 AC'!$B$3:$B$250,"*"&$D33&"*",'2025 AC'!C$3:C$250) -> 0 | AI33: =SUMIF('2025 AC'!$B$3:$B$250,"*"&$D33&"*",'2025 AC'!D$3:D$250) -> 0 | AJ33: =SUMIF('2025 AC'!$B$3:$B$250,"*"&$D33&"*",'2025 AC'!E$3:E$250) -> 0 | AK33: =SUMIF('2025 AC'!$B$3:$B$250,"*"&$D33&"*",'2025 AC'!F$3:F$250) -> 0 | AL33: =SUMIF('2025 AC'!$B$3:$B$250,"*"&$D33&"*",'2025 AC'!G$3:G$250) -> 0 | AM33: =SUMIF('2025 AC'!$B$3:$B$250,"*"&$D33&"*",'2025 AC'!H$3:H$250) -> 0 | AN33: =SUMIF('2025 AC'!$B$3:$B$250,"*"&$D33&"*",'2025 AC'!I$3:I$250) -> 42.37 | AO33: =SUMIF('2025 AC'!$B$3:$B$250,"*"&$D33&"*",'2025 AC'!J$3:J$250) -> 42.37 | ... AS33: =SUMIF('2025 AC'!$B$3:$B$250,"*"&$D33&"*",'2025 AC'!N$3:N$250) -> 0 | AT33: =SUM(AH33:AS33) -> 279.66 | AU33: =SUM(AH33:AJ33) -> 0 | AV33: =SUM(AK33:AM33) -> 0 | AW33: =SUM(AN33:AP33) -> 262.71 | AX33: =SUM(AQ33:AS33) -> 16.95 | AY33: =SUM(AU33:AX33) -> 279.66 | BA33: =SUMIF('2026 AC'!$B$3:$B$254,"*"&$D33&"*",'2026 AC'!C$3:C$254) -> 0 | BB33: =SUMIF('2026 AC'!$B$3:$B$254,"*"&$D33&"*",'2026 AC'!D$3:D$254) -> 42.37 | BC33: =SUMIF('2026 AC'!$B$3:$B$254,"*"&$D33&"*",'2026 AC'!E$3:E$254) -> 0 | BD33: =SUMIF('2026 AC'!$B$3:$B$254,"*"&$D33&"*",'2026 AC'!F$3:F$254) -> 0 | BE33: =SUMIF('2026 AC'!$B$3:$B$254,"*"&$D33&"*",'2026 AC'!G$3:G$254) -> 0 | BF33: =SUMIF('2026 AC'!$B$3:$B$254,"*"&$D33&"*",'2026 AC'!H$3:H$254) -> 0 | BG33: =SUMIF('2026 AC'!$B$3:$B$254,"*"&$D33&"*",'2026 AC'!I$3:I$254) -> 0 | BH33: =SUMIF('2026 AC'!$B$3:$B$254,"*"&$D33&"*",'2026 AC'!J$3:J$254) -> 0 | ... BL33: =SUMIF('2026 AC'!$B$3:$B$254,"*"&$D33&"*",'2026 AC'!N$3:N$254) -> 0 | BM33: =SUM(BA33:BL33) -> 42.37 | BN33: =SUM(BA33:BC33) -> 42.37 | BO33: =SUM(BD33:BF33) -> 0 | BP33: =SUM(BG33:BI33) -> 0 | BQ33: =SUM(BJ33:BL33) -> 0 | BR33: =SUM(BN33:BQ33) -> 42.37
A34: GUEST SERVICES - TELEPHONE | B34: 500-1007 | C34: GUEST SERVICES - TELEPHONE | D34: 500-1007 | E34: =SUMIF($BA$6:$BL$6,$E$6,$BA34:$BL34) -> 0 | F34: =SUMIF($AH$6:$AS$6,$F$6,$AH34:$AS34) -> 0 | G34: =IFERROR((E34-F34)/F34,0) -> 0 | H34: =SUMIF($BN$6:$BR$6,$H$6,$BN34:$BR34) -> 0 | I34: =SUMIF($AU$6:$AY$6,$I$6,$AU34:$AY34) -> 0 | J34: =IFERROR((H34-I34)/I34,0) -> 0 | K34: =BM34 -> 0 | L34: =SUM(AH34:AM34) -> 0 | M34: =IFERROR((K34-L34)/L34,0) -> 0 | O34: =SUMIF('2024 AC'!$B$3:$B$250,"*"&$D34&"*",'2024 AC'!C$3:C$250) -> 0 | P34: =SUMIF('2024 AC'!$B$3:$B$250,"*"&$D34&"*",'2024 AC'!D$3:D$250) -> 0 | Q34: =SUMIF('2024 AC'!$B$3:$B$250,"*"&$D34&"*",'2024 AC'!E$3:E$250) -> 0 | R34: =SUMIF('2024 AC'!$B$3:$B$250,"*"&$D34&"*",'2024 AC'!F$3:F$250) -> 0 | S34: =SUMIF('2024 AC'!$B$3:$B$250,"*"&$D34&"*",'2024 AC'!G$3:G$250) -> 0 | T34: =SUMIF('2024 AC'!$B$3:$B$250,"*"&$D34&"*",'2024 AC'!H$3:H$250) -> 0 | U34: =SUMIF('2024 AC'!$B$3:$B$250,"*"&$D34&"*",'2024 AC'!I$3:I$250) -> 0 | V34: =SUMIF('2024 AC'!$B$3:$B$250,"*"&$D34&"*",'2024 AC'!J$3:J$250) -> 0 | ... Z34: =SUMIF('2024 AC'!$B$3:$B$250,"*"&$D34&"*",'2024 AC'!N$3:N$250) -> 0 | AA34: =SUM(O34:Z34) -> 0 | AB34: =SUM(O34:Q34) -> 0 | AC34: =SUM(R34:T34) -> 0 | AD34: =SUM(U34:W34) -> 0 | AE34: =SUM(X34:Z34) -> 0 | AF34: =SUM(AB34:AE34) -> 0 | AH34: =SUMIF('2025 AC'!$B$3:$B$250,"*"&$D34&"*",'2025 AC'!C$3:C$250) -> 0 | AI34: =SUMIF('2025 AC'!$B$3:$B$250,"*"&$D34&"*",'2025 AC'!D$3:D$250) -> 0 | AJ34: =SUMIF('2025 AC'!$B$3:$B$250,"*"&$D34&"*",'2025 AC'!E$3:E$250) -> 0 | AK34: =SUMIF('2025 AC'!$B$3:$B$250,"*"&$D34&"*",'2025 AC'!F$3:F$250) -> 0 | AL34: =SUMIF('2025 AC'!$B$3:$B$250,"*"&$D34&"*",'2025 AC'!G$3:G$250) -> 0 | AM34: =SUMIF('2025 AC'!$B$3:$B$250,"*"&$D34&"*",'2025 AC'!H$3:H$250) -> 0 | AN34: =SUMIF('2025 AC'!$B$3:$B$250,"*"&$D34&"*",'2025 AC'!I$3:I$250) -> 0 | AO34: =SUMIF('2025 AC'!$B$3:$B$250,"*"&$D34&"*",'2025 AC'!J$3:J$250) -> 0 | ... AS34: =SUMIF('2025 AC'!$B$3:$B$250,"*"&$D34&"*",'2025 AC'!N$3:N$250) -> 0 | AT34: =SUM(AH34:AS34) -> 0 | AU34: =SUM(AH34:AJ34) -> 0 | AV34: =SUM(AK34:AM34) -> 0 | AW34: =SUM(AN34:AP34) -> 0 | AX34: =SUM(AQ34:AS34) -> 0 | AY34: =SUM(AU34:AX34) -> 0 | BA34: =SUMIF('2026 AC'!$B$3:$B$254,"*"&$D34&"*",'2026 AC'!C$3:C$254) -> 0 | BB34: =SUMIF('2026 AC'!$B$3:$B$254,"*"&$D34&"*",'2026 AC'!D$3:D$254) -> 0 | BC34: =SUMIF('2026 AC'!$B$3:$B$254,"*"&$D34&"*",'2026 AC'!E$3:E$254) -> 0 | BD34: =SUMIF('2026 AC'!$B$3:$B$254,"*"&$D34&"*",'2026 AC'!F$3:F$254) -> 0 | BE34: =SUMIF('2026 AC'!$B$3:$B$254,"*"&$D34&"*",'2026 AC'!G$3:G$254) -> 0 | BF34: =SUMIF('2026 AC'!$B$3:$B$254,"*"&$D34&"*",'2026 AC'!H$3:H$254) -> 0 | BG34: =SUMIF('2026 AC'!$B$3:$B$254,"*"&$D34&"*",'2026 AC'!I$3:I$254) -> 0 | BH34: =SUMIF('2026 AC'!$B$3:$B$254,"*"&$D34&"*",'2026 AC'!J$3:J$254) -> 0 | ... BL34: =SUMIF('2026 AC'!$B$3:$B$254,"*"&$D34&"*",'2026 AC'!N$3:N$254) -> 0 | BM34: =SUM(BA34:BL34) -> 0 | BN34: =SUM(BA34:BC34) -> 0 | BO34: =SUM(BD34:BF34) -> 0 | BP34: =SUM(BG34:BI34) -> 0 | BQ34: =SUM(BJ34:BL34) -> 0 | BR34: =SUM(BN34:BQ34) -> 0
A35: GUEST SERVICES - TRANSPORTATION | B35: 500-1008 | C35: GUEST SERVICES - TRANSPORTATION | D35: 500-1008 | E35: =SUMIF($BA$6:$BL$6,$E$6,$BA35:$BL35) -> 0 | F35: =SUMIF($AH$6:$AS$6,$F$6,$AH35:$AS35) -> 275.08 | G35: =IFERROR((E35-F35)/F35,0) -> -1 | H35: =SUMIF($BN$6:$BR$6,$H$6,$BN35:$BR35) -> 0 | I35: =SUMIF($AU$6:$AY$6,$I$6,$AU35:$AY35) -> 616.77 | J35: =(H35-I35)/I35 -> -1 | K35: =BM35 -> 254.25 | L35: =SUM(AH35:AM35) -> 676.26 | M35: =(K35-L35)/L35 -> -0.62403513 | O35: =SUMIF('2024 AC'!$B$3:$B$250,"*"&$D35&"*",'2024 AC'!C$3:C$250) -> 0 | P35: =SUMIF('2024 AC'!$B$3:$B$250,"*"&$D35&"*",'2024 AC'!D$3:D$250) -> 172.42 | Q35: =SUMIF('2024 AC'!$B$3:$B$250,"*"&$D35&"*",'2024 AC'!E$3:E$250) -> 0 | R35: =SUMIF('2024 AC'!$B$3:$B$250,"*"&$D35&"*",'2024 AC'!F$3:F$250) -> 84.75 | S35: =SUMIF('2024 AC'!$B$3:$B$250,"*"&$D35&"*",'2024 AC'!G$3:G$250) -> 338.99 | T35: =SUMIF('2024 AC'!$B$3:$B$250,"*"&$D35&"*",'2024 AC'!H$3:H$250) -> 169.5 | U35: =SUMIF('2024 AC'!$B$3:$B$250,"*"&$D35&"*",'2024 AC'!I$3:I$250) -> 0 | V35: =SUMIF('2024 AC'!$B$3:$B$250,"*"&$D35&"*",'2024 AC'!J$3:J$250) -> 169.5 | ... Z35: =SUMIF('2024 AC'!$B$3:$B$250,"*"&$D35&"*",'2024 AC'!N$3:N$250) -> 292.38 | AA35: =SUM(O35:Z35) -> 1464.16 | AB35: =SUM(O35:Q35) -> 172.42 | AC35: =SUM(R35:T35) -> 593.24 | AD35: =SUM(U35:W35) -> 254.25 | AE35: =SUM(X35:Z35) -> 444.25 | AF35: =SUM(AB35:AE35) -> 1464.16 | AH35: =SUMIF('2025 AC'!$B$3:$B$250,"*"&$D35&"*",'2025 AC'!C$3:C$250) -> 8.65 | AI35: =SUMIF('2025 AC'!$B$3:$B$250,"*"&$D35&"*",'2025 AC'!D$3:D$250) -> 50.84 | AJ35: =SUMIF('2025 AC'!$B$3:$B$250,"*"&$D35&"*",'2025 AC'!E$3:E$250) -> 0 | AK35: =SUMIF('2025 AC'!$B$3:$B$250,"*"&$D35&"*",'2025 AC'!F$3:F$250) -> 0 | AL35: =SUMIF('2025 AC'!$B$3:$B$250,"*"&$D35&"*",'2025 AC'!G$3:G$250) -> 341.69 | AM35: =SUMIF('2025 AC'!$B$3:$B$250,"*"&$D35&"*",'2025 AC'!H$3:H$250) -> 275.08 | AN35: =SUMIF('2025 AC'!$B$3:$B$250,"*"&$D35&"*",'2025 AC'!I$3:I$250) -> 121.53 | AO35: =SUMIF('2025 AC'!$B$3:$B$250,"*"&$D35&"*",'2025 AC'!J$3:J$250) -> 169.5 | ... AS35: =SUMIF('2025 AC'!$B$3:$B$250,"*"&$D35&"*",'2025 AC'!N$3:N$250) -> 0 | AT35: =SUM(AH35:AS35) -> 967.29 | AU35: =SUM(AH35:AJ35) -> 59.49 | AV35: =SUM(AK35:AM35) -> 616.77 | AW35: =SUM(AN35:AP35) -> 291.03 | AX35: =SUM(AQ35:AS35) -> 0 | AY35: =SUM(AU35:AX35) -> 967.29 | BA35: =SUMIF('2026 AC'!$B$3:$B$254,"*"&$D35&"*",'2026 AC'!C$3:C$254) -> 254.25 | BB35: =SUMIF('2026 AC'!$B$3:$B$254,"*"&$D35&"*",'2026 AC'!D$3:D$254) -> 0 | BC35: =SUMIF('2026 AC'!$B$3:$B$254,"*"&$D35&"*",'2026 AC'!E$3:E$254) -> 0 | BD35: =SUMIF('2026 AC'!$B$3:$B$254,"*"&$D35&"*",'2026 AC'!F$3:F$254) -> 0 | BE35: =SUMIF('2026 AC'!$B$3:$B$254,"*"&$D35&"*",'2026 AC'!G$3:G$254) -> 0 | BF35: =SUMIF('2026 AC'!$B$3:$B$254,"*"&$D35&"*",'2026 AC'!H$3:H$254) -> 0 | BG35: =SUMIF('2026 AC'!$B$3:$B$254,"*"&$D35&"*",'2026 AC'!I$3:I$254) -> 0 | BH35: =SUMIF('2026 AC'!$B$3:$B$254,"*"&$D35&"*",'2026 AC'!J$3:J$254) -> 0 | ... BL35: =SUMIF('2026 AC'!$B$3:$B$254,"*"&$D35&"*",'2026 AC'!N$3:N$254) -> 0 | BM35: =SUM(BA35:BL35) -> 254.25 | BN35: =SUM(BA35:BC35) -> 254.25 | BO35: =SUM(BD35:BF35) -> 0 | BP35: =SUM(BG35:BI35) -> 0 | BQ35: =SUM(BJ35:BL35) -> 0 | BR35: =SUM(BN35:BQ35) -> 254.25
A36: GUEST SERVICES - ROOM KEY CARD | B36: 500-1009 | C36: GUEST SERVICES - ROOM KEY CARD | D36: 500-1009 | E36: =SUMIF($BA$6:$BL$6,$E$6,$BA36:$BL36) -> 0 | F36: =SUMIF($AH$6:$AS$6,$F$6,$AH36:$AS36) -> 0 | G36: =IFERROR((E36-F36)/F36,0) -> 0 | H36: =SUMIF($BN$6:$BR$6,$H$6,$BN36:$BR36) -> 10 | I36: =SUMIF($AU$6:$AY$6,$I$6,$AU36:$AY36) -> 0 | J36: =IFERROR((H36-I36)/I36,1) -> 1 | K36: =BM36 -> 10 | L36: =SUM(AH36:AM36) -> 0 | M36: =IFERROR((K36-L36)/L36,1) -> 1 | O36: =SUMIF('2024 AC'!$B$3:$B$250,"*"&$D36&"*",'2024 AC'!C$3:C$250) -> 0 | P36: =SUMIF('2024 AC'!$B$3:$B$250,"*"&$D36&"*",'2024 AC'!D$3:D$250) -> 0 | Q36: =SUMIF('2024 AC'!$B$3:$B$250,"*"&$D36&"*",'2024 AC'!E$3:E$250) -> 0 | R36: =SUMIF('2024 AC'!$B$3:$B$250,"*"&$D36&"*",'2024 AC'!F$3:F$250) -> 0 | S36: =SUMIF('2024 AC'!$B$3:$B$250,"*"&$D36&"*",'2024 AC'!G$3:G$250) -> 0 | T36: =SUMIF('2024 AC'!$B$3:$B$250,"*"&$D36&"*",'2024 AC'!H$3:H$250) -> 0 | U36: =SUMIF('2024 AC'!$B$3:$B$250,"*"&$D36&"*",'2024 AC'!I$3:I$250) -> 0 | V36: =SUMIF('2024 AC'!$B$3:$B$250,"*"&$D36&"*",'2024 AC'!J$3:J$250) -> 0 | ... Z36: =SUMIF('2024 AC'!$B$3:$B$250,"*"&$D36&"*",'2024 AC'!N$3:N$250) -> 0 | AA36: =SUM(O36:Z36) -> 20 | AB36: =SUM(O36:Q36) -> 0 | AC36: =SUM(R36:T36) -> 0 | AD36: =SUM(U36:W36) -> 10 | AE36: =SUM(X36:Z36) -> 10 | AF36: =SUM(AB36:AE36) -> 20 | AH36: =SUMIF('2025 AC'!$B$3:$B$250,"*"&$D36&"*",'2025 AC'!C$3:C$250) -> 0 | AI36: =SUMIF('2025 AC'!$B$3:$B$250,"*"&$D36&"*",'2025 AC'!D$3:D$250) -> 0 | AJ36: =SUMIF('2025 AC'!$B$3:$B$250,"*"&$D36&"*",'2025 AC'!E$3:E$250) -> 0 | AK36: =SUMIF('2025 AC'!$B$3:$B$250,"*"&$D36&"*",'2025 AC'!F$3:F$250) -> 0 | AL36: =SUMIF('2025 AC'!$B$3:$B$250,"*"&$D36&"*",'2025 AC'!G$3:G$250) -> 0 | AM36: =SUMIF('2025 AC'!$B$3:$B$250,"*"&$D36&"*",'2025 AC'!H$3:H$250) -> 0 | AN36: =SUMIF('2025 AC'!$B$3:$B$250,"*"&$D36&"*",'2025 AC'!I$3:I$250) -> 0 | AO36: =SUMIF('2025 AC'!$B$3:$B$250,"*"&$D36&"*",'2025 AC'!J$3:J$250) -> 0 | ... AS36: =SUMIF('2025 AC'!$B$3:$B$250,"*"&$D36&"*",'2025 AC'!N$3:N$250) -> 9.18 | AT36: =SUM(AH36:AS36) -> 9.18 | AU36: =SUM(AH36:AJ36) -> 0 | AV36: =SUM(AK36:AM36) -> 0 | AW36: =SUM(AN36:AP36) -> 0 | AX36: =SUM(AQ36:AS36) -> 9.18 | AY36: =SUM(AU36:AX36) -> 9.18 | BA36: =SUMIF('2026 AC'!$B$3:$B$254,"*"&$D36&"*",'2026 AC'!C$3:C$254) -> 0 | BB36: =SUMIF('2026 AC'!$B$3:$B$254,"*"&$D36&"*",'2026 AC'!D$3:D$254) -> 0 | BC36: =SUMIF('2026 AC'!$B$3:$B$254,"*"&$D36&"*",'2026 AC'!E$3:E$254) -> 0 | BD36: =SUMIF('2026 AC'!$B$3:$B$254,"*"&$D36&"*",'2026 AC'!F$3:F$254) -> 0 | BE36: =SUMIF('2026 AC'!$B$3:$B$254,"*"&$D36&"*",'2026 AC'!G$3:G$254) -> 10 | BF36: =SUMIF('2026 AC'!$B$3:$B$254,"*"&$D36&"*",'2026 AC'!H$3:H$254) -> 0 | BG36: =SUMIF('2026 AC'!$B$3:$B$254,"*"&$D36&"*",'2026 AC'!I$3:I$254) -> 0 | BH36: =SUMIF('2026 AC'!$B$3:$B$254,"*"&$D36&"*",'2026 AC'!J$3:J$254) -> 0 | ... BL36: =SUMIF('2026 AC'!$B$3:$B$254,"*"&$D36&"*",'2026 AC'!N$3:N$254) -> 0 | BM36: =SUM(BA36:BL36) -> 10 | BN36: =SUM(BA36:BC36) -> 0 | BO36: =SUM(BD36:BF36) -> 10 | BP36: =SUM(BG36:BI36) -> 0 | BQ36: =SUM(BJ36:BL36) -> 0 | BR36: =SUM(BN36:BQ36) -> 10
A37: ROOM SERVICE CHARGE | B37: 500-RMSC | C37: ROOM SERVICE CHARGE | D37: 500-RMSC | E37: =SUMIF($BA$6:$BL$6,$E$6,$BA37:$BL37) -> 10501.29 | F37: =SUMIF($AH$6:$AS$6,$F$6,$AH37:$AS37) -> 13972.88 | G37: =(E37-F37)/F37 -> -0.248452 | H37: =SUMIF($BN$6:$BR$6,$H$6,$BN37:$BR37) -> 32536.55 | I37: =SUMIF($AU$6:$AY$6,$I$6,$AU37:$AY37) -> 44079.39 | J37: =(H37-I37)/I37 -> -0.26186479 | K37: =BM37 -> 62939.23 | L37: =SUM(AH37:AM37) -> 71262.65 | M37: =(K37-L37)/L37 -> -0.11679919 | O37: =SUMIF('2024 AC'!$B$3:$B$250,"*"&$D37&"*",'2024 AC'!C$3:C$250) -> 16553.62 | P37: =SUMIF('2024 AC'!$B$3:$B$250,"*"&$D37&"*",'2024 AC'!D$3:D$250) -> 20560.03 | Q37: =SUMIF('2024 AC'!$B$3:$B$250,"*"&$D37&"*",'2024 AC'!E$3:E$250) -> 7550.17 | R37: =SUMIF('2024 AC'!$B$3:$B$250,"*"&$D37&"*",'2024 AC'!F$3:F$250) -> 10739.64 | S37: =SUMIF('2024 AC'!$B$3:$B$250,"*"&$D37&"*",'2024 AC'!G$3:G$250) -> 17809.02 | T37: =SUMIF('2024 AC'!$B$3:$B$250,"*"&$D37&"*",'2024 AC'!H$3:H$250) -> 13795.41 | U37: =SUMIF('2024 AC'!$B$3:$B$250,"*"&$D37&"*",'2024 AC'!I$3:I$250) -> 16256.45 | V37: =SUMIF('2024 AC'!$B$3:$B$250,"*"&$D37&"*",'2024 AC'!J$3:J$250) -> 25670.24 | ... Z37: =SUMIF('2024 AC'!$B$3:$B$250,"*"&$D37&"*",'2024 AC'!N$3:N$250) -> 10189.48 | AA37: =SUM(O37:Z37) -> 187960.29 | AB37: =SUM(O37:Q37) -> 44663.82 | AC37: =SUM(R37:T37) -> 42344.07 | AD37: =SUM(U37:W37) -> 54340.43 | AE37: =SUM(X37:Z37) -> 46611.97 | AF37: =SUM(AB37:AE37) -> 187960.29 | AH37: =SUMIF('2025 AC'!$B$3:$B$250,"*"&$D37&"*",'2025 AC'!C$3:C$250) -> 11246.65 | AI37: =SUMIF('2025 AC'!$B$3:$B$250,"*"&$D37&"*",'2025 AC'!D$3:D$250) -> 9087.34 | AJ37: =SUMIF('2025 AC'!$B$3:$B$250,"*"&$D37&"*",'2025 AC'!E$3:E$250) -> 6849.27 | AK37: =SUMIF('2025 AC'!$B$3:$B$250,"*"&$D37&"*",'2025 AC'!F$3:F$250) -> 12673.56 | AL37: =SUMIF('2025 AC'!$B$3:$B$250,"*"&$D37&"*",'2025 AC'!G$3:G$250) -> 17432.95 | AM37: =SUMIF('2025 AC'!$B$3:$B$250,"*"&$D37&"*",'2025 AC'!H$3:H$250) -> 13972.88 | AN37: =SUMIF('2025 AC'!$B$3:$B$250,"*"&$D37&"*",'2025 AC'!I$3:I$250) -> 15312.74 | AO37: =SUMIF('2025 AC'!$B$3:$B$250,"*"&$D37&"*",'2025 AC'!J$3:J$250) -> 14506.83 | ... AS37: =SUMIF('2025 AC'!$B$3:$B$250,"*"&$D37&"*",'2025 AC'!N$3:N$250) -> 11937.53 | AT37: =SUM(AH37:AS37) -> 156794.07 | AU37: =SUM(AH37:AJ37) -> 27183.26 | AV37: =SUM(AK37:AM37) -> 44079.39 | AW37: =SUM(AN37:AP37) -> 47738.03 | AX37: =SUM(AQ37:AS37) -> 37793.39 | AY37: =SUM(AU37:AX37) -> 156794.07 | BA37: =SUMIF('2026 AC'!$B$3:$B$254,"*"&$D37&"*",'2026 AC'!C$3:C$254) -> 12036.46 | BB37: =SUMIF('2026 AC'!$B$3:$B$254,"*"&$D37&"*",'2026 AC'!D$3:D$254) -> 8679.59 | BC37: =SUMIF('2026 AC'!$B$3:$B$254,"*"&$D37&"*",'2026 AC'!E$3:E$254) -> 9686.63 | BD37: =SUMIF('2026 AC'!$B$3:$B$254,"*"&$D37&"*",'2026 AC'!F$3:F$254) -> 14581.56 | BE37: =SUMIF('2026 AC'!$B$3:$B$254,"*"&$D37&"*",'2026 AC'!G$3:G$254) -> 7453.7 | BF37: =SUMIF('2026 AC'!$B$3:$B$254,"*"&$D37&"*",'2026 AC'!H$3:H$254) -> 10501.29 | BG37: =SUMIF('2026 AC'!$B$3:$B$254,"*"&$D37&"*",'2026 AC'!I$3:I$254) -> 0 | BH37: =SUMIF('2026 AC'!$B$3:$B$254,"*"&$D37&"*",'2026 AC'!J$3:J$254) -> 0 | ... BL37: =SUMIF('2026 AC'!$B$3:$B$254,"*"&$D37&"*",'2026 AC'!N$3:N$254) -> 0 | BM37: =SUM(BA37:BL37) -> 62939.23 | BN37: =SUM(BA37:BC37) -> 30402.68 | BO37: =SUM(BD37:BF37) -> 32536.55 | BP37: =SUM(BG37:BI37) -> 0 | BQ37: =SUM(BJ37:BL37) -> 0 | BR37: =SUM(BN37:BQ37) -> 62939.23
A38: F&B REVENUE | B38: 500-2000 | C38: F&B REVENUE | D38: 500-2000 | E38: =SUMIF($BA$6:$BL$6,$E$6,$BA38:$BL38) -> 17895.14 | F38: =SUMIF($AH$6:$AS$6,$F$6,$AH38:$AS38) -> 12236.47 | G38: =(E38-F38)/F38 -> 0.46244301 | H38: =SUMIF($BN$6:$BR$6,$H$6,$BN38:$BR38) -> 38463.62 | I38: =SUMIF($AU$6:$AY$6,$I$6,$AU38:$AY38) -> 49885.46 | J38: =(H38-I38)/I38 -> -0.2289613 | K38: =BM38 -> 194334.4 | L38: =SUM(AH38:AM38) -> 245457.27 | M38: =(K38-L38)/L38 -> -0.20827605 | O38: =SUMIF('2024 AC'!$B$3:$B$250,"*"&$D38&"*",'2024 AC'!C$3:C$250) -> 25359.38 | P38: =SUMIF('2024 AC'!$B$3:$B$250,"*"&$D38&"*",'2024 AC'!D$3:D$250) -> 28424.25 | Q38: =SUMIF('2024 AC'!$B$3:$B$250,"*"&$D38&"*",'2024 AC'!E$3:E$250) -> 97945.96 | R38: =SUMIF('2024 AC'!$B$3:$B$250,"*"&$D38&"*",'2024 AC'!F$3:F$250) -> 70797.07 | S38: =SUMIF('2024 AC'!$B$3:$B$250,"*"&$D38&"*",'2024 AC'!G$3:G$250) -> 33305.83 | T38: =SUMIF('2024 AC'!$B$3:$B$250,"*"&$D38&"*",'2024 AC'!H$3:H$250) -> 29357.49 | U38: =SUMIF('2024 AC'!$B$3:$B$250,"*"&$D38&"*",'2024 AC'!I$3:I$250) -> 36166 | V38: =SUMIF('2024 AC'!$B$3:$B$250,"*"&$D38&"*",'2024 AC'!J$3:J$250) -> 33224.16 | ... Z38: =SUMIF('2024 AC'!$B$3:$B$250,"*"&$D38&"*",'2024 AC'!N$3:N$250) -> 19440.23 | AA38: =SUM(O38:Z38) -> 421190.4 | AB38: =SUM(O38:Q38) -> 151729.59 | AC38: =SUM(R38:T38) -> 133460.39 | AD38: =SUM(U38:W38) -> 89795.43 | AE38: =SUM(X38:Z38) -> 46204.99 | AF38: =SUM(AB38:AE38) -> 421190.4 | AH38: =SUMIF('2025 AC'!$B$3:$B$250,"*"&$D38&"*",'2025 AC'!C$3:C$250) -> 11237.62 | AI38: =SUMIF('2025 AC'!$B$3:$B$250,"*"&$D38&"*",'2025 AC'!D$3:D$250) -> 11051.17 | AJ38: =SUMIF('2025 AC'!$B$3:$B$250,"*"&$D38&"*",'2025 AC'!E$3:E$250) -> 173283.02 | AK38: =SUMIF('2025 AC'!$B$3:$B$250,"*"&$D38&"*",'2025 AC'!F$3:F$250) -> 22433.86 | AL38: =SUMIF('2025 AC'!$B$3:$B$250,"*"&$D38&"*",'2025 AC'!G$3:G$250) -> 15215.13 | AM38: =SUMIF('2025 AC'!$B$3:$B$250,"*"&$D38&"*",'2025 AC'!H$3:H$250) -> 12236.47 | AN38: =SUMIF('2025 AC'!$B$3:$B$250,"*"&$D38&"*",'2025 AC'!I$3:I$250) -> 13176.76 | AO38: =SUMIF('2025 AC'!$B$3:$B$250,"*"&$D38&"*",'2025 AC'!J$3:J$250) -> 12812.24 | ... AS38: =SUMIF('2025 AC'!$B$3:$B$250,"*"&$D38&"*",'2025 AC'!N$3:N$250) -> 15761.74 | AT38: =SUM(AH38:AS38) -> 322508.96 | AU38: =SUM(AH38:AJ38) -> 195571.81 | AV38: =SUM(AK38:AM38) -> 49885.46 | AW38: =SUM(AN38:AP38) -> 38989.86 | AX38: =SUM(AQ38:AS38) -> 38061.83 | AY38: =SUM(AU38:AX38) -> 322508.96 | BA38: =SUMIF('2026 AC'!$B$3:$B$254,"*"&$D38&"*",'2026 AC'!C$3:C$254) -> 18794.09 | BB38: =SUMIF('2026 AC'!$B$3:$B$254,"*"&$D38&"*",'2026 AC'!D$3:D$254) -> 27030.97 | BC38: =SUMIF('2026 AC'!$B$3:$B$254,"*"&$D38&"*",'2026 AC'!E$3:E$254) -> 110045.72 | BD38: =SUMIF('2026 AC'!$B$3:$B$254,"*"&$D38&"*",'2026 AC'!F$3:F$254) -> 10962.42 | BE38: =SUMIF('2026 AC'!$B$3:$B$254,"*"&$D38&"*",'2026 AC'!G$3:G$254) -> 9606.06 | BF38: =SUMIF('2026 AC'!$B$3:$B$254,"*"&$D38&"*",'2026 AC'!H$3:H$254) -> 17895.14 | BG38: =SUMIF('2026 AC'!$B$3:$B$254,"*"&$D38&"*",'2026 AC'!I$3:I$254) -> 0 | BH38: =SUMIF('2026 AC'!$B$3:$B$254,"*"&$D38&"*",'2026 AC'!J$3:J$254) -> 0 | ... BL38: =SUMIF('2026 AC'!$B$3:$B$254,"*"&$D38&"*",'2026 AC'!N$3:N$254) -> 0 | BM38: =SUM(BA38:BL38) -> 194334.4 | BN38: =SUM(BA38:BC38) -> 155870.78 | BO38: =SUM(BD38:BF38) -> 38463.62 | BP38: =SUM(BG38:BI38) -> 0 | BQ38: =SUM(BJ38:BL38) -> 0 | BR38: =SUM(BN38:BQ38) -> 194334.4
